<?xml version="1.0" ?>
<!-- =================================================================================== -->
<!-- |    This document was autogenerated by xacro from tiago.urdf.xacro               | -->
<!-- |    EDITING THIS FILE BY HAND IS NOT RECOMMENDED                                 | -->
<!-- =================================================================================== -->
<!-- 
  Copyright (c) 2024 PAL Robotics S.L. All rights reserved.

  Licensed under the Apache License, Version 2.0 (the "License");
  you may not use this file except in compliance with the License.
  You may obtain a copy of the License at

      http://www.apache.org/licenses/LICENSE-2.0

  Unless required by applicable law or agreed to in writing, software
  distributed under the License is distributed on an "AS IS" BASIS,
  WITHOUT WARRANTIES OR CONDITIONS OF ANY KIND, either express or implied.
  See the License for the specific language governing permissions and
  limitations under the License.
 -->
<!--
  - Base
  - Laser
  - Arm
  - Wrist
  - FT Sensor
  - End effector
  - Camera
-->
<robot name="tiago">
  <!-- ARGUMENTS -->
  <!-- PROPERTIES -->
  <!-- INCLUDES -->
  <!-- PROPERTIES -->
  <!-- MACRO DEFINITION-->
  <material name="Blue">
    <color rgba="0.0 0.0 0.8 1.0"/>
  </material>
  <material name="Green">
    <color rgba="0.0 0.8 0.0 1.0"/>
  </material>
  <material name="Grey">
    <color rgba="0.7 0.7 0.7 1.0"/>
  </material>
  <material name="LightGrey">
    <color rgba="0.9 0.9 0.9 1.0"/>
  </material>
  <material name="DarkGrey">
    <color rgba="0.1 0.1 0.1 1.0"/>
  </material>
  <material name="Red">
    <color rgba="0.8 0.0 0.0 1.0"/>
  </material>
  <material name="White">
    <color rgba="1.0 1.0 1.0 1.0"/>
  </material>
  <material name="Yellow">
    <color rgba="0.96 0.88 0.14 1.0"/>
  </material>
  <material name="Black">
    <color rgba="0.0 0.0 0.0 1.0"/>
  </material>
  <material name="FlatBlack">
    <color rgba="0.09 0.09 0.09 1.0"/>
  </material>
  <material name="Orange">
    <color rgba="1.0 0.487 0.0 1.0"/>
  </material>
  <material name="pal/Orange">
    <color rgba="0.91373 0.61568 0.29411 1.0"/>
  </material>
  <material name="pal/DarkGrey">
    <color rgba="0.29804 0.29804 0.29804 1"/>
  </material>
  <!-- MACRO DEFINITION -->
  <!-- MACRO DEFINITION -->
  <!-- MACRO DEFINITION -->
  <!-- MACRO DEFINITION -->
  <!-- ROBOT DEFINITION -->
  
  
  
  <!-- Base -->
  <link name="base_link">
   
    <visual>
      <origin rpy="0 0 0" xyz="0 0 0"/>
      <geometry>
        <mesh filename="package://pmb2_description/meshes/base/base.stl"/>
      </geometry>
      <material name="White"/>
    </visual>
    <collision>
      <origin rpy="0 0 0" xyz="0 0 0"/>
      <geometry>
        <mesh filename="package://pmb2_description/meshes/base/high_resolution/base_collision.stl"/>
      </geometry>
      <material name="White"/>
    </collision>
  </link>
  <!-- Base footprint -->
  <link name="base_footprint"/>
  <joint name="base_footprint_joint" type="fixed">
    <origin rpy="0 0 0" xyz="0 0 0.0985"/>
    <child link="base_link"/>
    <parent link="base_footprint"/>
  </joint>
  <link name="base_cover_link">
    
    <visual>
      <origin rpy="0 0 0" xyz="0 0 0"/>
      <geometry>
        <mesh filename="package://pmb2_description/meshes/base/base_ring.stl"/>
      </geometry>
      <material name="Orange"/>
    </visual>
  </link>
  <joint name="cover_joint" type="fixed">
    <parent link="base_footprint"/>
    <child link="base_cover_link"/>
    <origin rpy="0 0 0" xyz="0 0 0.13"/>
  </joint>
  <gazebo reference="base_cover_link">
    <material>Gazebo/Orange</material>
  </gazebo>
  
  <!-- Odometry plugin for ground truth -->
  <gazebo>
    <plugin filename="libgazebo_world_odometry.so" name="gazebo_ros_odometry">
      <frame_name>world</frame_name>
      <body_name>base_footprint</body_name>
      <topic_name>ground_truth_odom</topic_name>
      <update_rate>100.0</update_rate>
    </plugin>
  </gazebo>
  <!-- Bottom fixed part of column -->
  <link name="torso_fixed_link">
    
    <visual>
      <origin rpy="0 0 0" xyz="0 0 0"/>
      <geometry>
        <mesh filename="package://tiago_description/meshes/torso/torso_fix.stl" scale="1 1 1"/>
      </geometry>
      <material name="LightGrey"/>
    </visual>
    <collision>
      <origin rpy="0 0 0" xyz="0.085 0.0 0.02"/>
      <geometry>
        <box size="0.4 0.25 0.04"/>
      </geometry>
    </collision>
    <collision>
      <origin rpy="0 0 0" xyz="0 0 0.05"/>
      <geometry>
        <box size="0.25 0.25 0.1"/>
      </geometry>
    </collision>
  </link>
  <joint name="torso_fixed_joint" type="fixed">
    <origin rpy="0 0 0" xyz="-0.062 0.0 0.193"/>
    <parent link="base_link"/>
    <child link="torso_fixed_link"/>
    <axis xyz="0 0 0"/>
  </joint>
 
  <link name="torso_lift_link">
   
    <visual>
      <origin rpy="0 0 0" xyz="0 0 0"/>
      <geometry>
        <mesh filename="package://tiago_description/meshes/torso/torso_lift_with_arm.stl" scale="1 1 1"/>
      </geometry>
      <material name="White"/>
    </visual>
    <collision>
      <origin rpy="0 0 0" xyz="0 0 0"/>
      <geometry>
        <mesh filename="package://tiago_description/meshes/torso/torso_lift_collision_core.dae" scale="1 1 1"/>
      </geometry>
      <material name="LightGrey"/>
    </collision>
    <collision>
      <origin rpy="0 0 0" xyz="0 0 0"/>
      <geometry>
        <mesh filename="package://tiago_description/meshes/torso/torso_lift_collision_shoulder.dae" scale="1 1 1"/>
      </geometry>
      <material name="LightGrey"/>
    </collision>
    <collision>
      <origin rpy="0 0 0" xyz="0 0 0"/>
      <geometry>
        <mesh filename="package://tiago_description/meshes/torso/torso_lift_collision_neck.dae" scale="1 1 1"/>
      </geometry>
      <material name="LightGrey"/>
    </collision>
  </link>
  <joint name="torso_lift_joint" type="fixed"> <!--prismatic joint/cago_note-->
    <origin rpy="0.0 0.0 0.0" xyz="0.0 0.0 0.597"/>
    <parent link="torso_fixed_link"/>
    <child link="torso_lift_link"/>
    <axis xyz="0 0 1"/>
    <limit effort="2000" lower="0" upper="0.35" velocity="0.07"/>
    <calibration rising="0.0"/>
    <dynamics damping="1000"/>
    <safety_controller k_position="20" k_velocity="20" soft_lower_limit="0.0" soft_upper_limit="0.35"/>
  </joint>
  <!-- Shoulder -->
  <link name="arm_1_link">
    
    <!-- M90 module -->
    <visual>
      <origin rpy="0 0 0" xyz="0 0 0"/>
      <geometry>
        <mesh filename="package://tiago_description/meshes/arm/arm_1.stl" scale="1 1 1"/>
      </geometry>
      <material name="White"/>
    </visual>
    <collision>
      <origin rpy="0 0 0" xyz="0 0 0"/>
      <geometry>
        <mesh filename="package://tiago_description/meshes/arm/arm_1_collision.dae" scale="1 1 1"/>
      </geometry>
    </collision>
  </link>
  <joint name="arm_1_joint" type="revolute">
    <parent link="torso_lift_link"/>
    <child link="arm_1_link"/>
    <origin rpy="0 0 -1.5707963267948966" xyz="0.15505 0.014 -0.151"/>
    <axis xyz="0 0 1"/>
    <limit effort="43.0" lower="0.0" upper="2.748893571891069" velocity="1.95"/>
    <dynamics damping="40.0" friction="1.0"/>
    <safety_controller k_position="20" k_velocity="20" soft_lower_limit="0.07" soft_upper_limit="2.678893571891069"/>
  </joint>
  <link name="arm_2_link">
    
    <visual>
      <!-- <origin xyz="0 0 0" rpy="${180 * deg_to_rad} ${0 * deg_to_rad} ${-90 * deg_to_rad}" /> -->
      <origin rpy="0.0 0.0 0.0" xyz="0 0 0"/>
      <geometry>
        <mesh filename="package://tiago_description/meshes/arm/arm_2.stl" scale="1 1 1"/>
      </geometry>
      <material name="DarkGrey"/>
    </visual>
    <collision>
      <!-- <origin xyz="0 0 0" rpy="${180 * deg_to_rad} ${0 * deg_to_rad} ${-90 * deg_to_rad}" /> -->
      <origin rpy="0.0 0.0 0.0" xyz="0 0 0"/>
      <geometry>
        <mesh filename="package://tiago_description/meshes/arm/arm_2_collision.dae" scale="1 1 1"/>
      </geometry>
    </collision>
  </link>
  <joint name="arm_2_joint" type="revolute">
    <parent link="arm_1_link"/>
    <child link="arm_2_link"/>
    <origin rpy="1.5707963267948966 0.0 0.0" xyz="0.125 0.0195 -0.031"/>
    <axis xyz="0 0 1"/>
    <limit effort="43.0" lower="-1.5707963267948966" upper="1.090830782496456" velocity="1.95"/>
    <dynamics damping="40.0" friction="1.0"/>
    <safety_controller k_position="20" k_velocity="20" soft_lower_limit="-1.5007963267948965" soft_upper_limit="1.020830782496456"/>
  </joint>
  <link name="arm_3_link">
    
    <visual>
      <origin rpy="0 0 0" xyz="0 0 0"/>
      <geometry>
        <mesh filename="package://tiago_description/meshes/arm/arm_3.stl" scale="1 1 1"/>
      </geometry>
      <material name="DarkGrey"/>
    </visual>
    <collision>
      <origin rpy="0 0 0" xyz="0 0 0"/>
      <geometry>
        <mesh filename="package://tiago_description/meshes/arm/arm_3_collision.dae" scale="1 1 1"/>
      </geometry>
    </collision>
  </link>
  <joint name="arm_3_joint" type="revolute">
    <parent link="arm_2_link"/>
    <child link="arm_3_link"/>
    <origin rpy="-1.5707963267948966 0.0 1.5707963267948966" xyz="0.0895 0.0 -0.0015"/>
    <axis xyz="0 0 1"/>
    <limit effort="26" lower="-3.5342917352885173" upper="1.5707963267948966" velocity="2.35"/>
    <dynamics damping="40.0" friction="1.0"/>
    <safety_controller k_position="20" k_velocity="20" soft_lower_limit="-3.4642917352885174" soft_upper_limit="1.5007963267948965"/>
  </joint>
  <!-- Elbow -->
  <link name="arm_4_link">
    
    <visual>
      <origin rpy="0 0 0" xyz="0 0 0"/>
      <geometry>
        <mesh filename="package://tiago_description/meshes/arm/arm_4.stl" scale="1 1 1"/>
      </geometry>
      <material name="DarkGrey"/>
    </visual>
    <collision>
      <origin rpy="0 0 0" xyz="0 0 0"/>
      <geometry>
        <mesh filename="package://tiago_description/meshes/arm/arm_4_collision.dae" scale="1 1 1"/>
      </geometry>
    </collision>
  </link>
  <joint name="arm_4_joint" type="revolute">
    <parent link="arm_3_link"/>
    <child link="arm_4_link"/>
    <origin rpy="-1.5707963267948966 -1.5707963267948966 0.0" xyz="-0.02 -0.027 -0.222"/>
    <axis xyz="0 0 1"/>
    <limit effort="26" lower="-0.39269908169872414" upper="2.356194490192345" velocity="2.35"/>
    <dynamics damping="40.0" friction="1.0"/>
    <safety_controller k_position="20" k_velocity="20" soft_lower_limit="-0.32269908169872413" soft_upper_limit="2.286194490192345"/>
  </joint>
  <gazebo reference="arm_1_link">
    <mu1>0.9</mu1>
    <mu2>0.9</mu2>
    <material>Gazebo/DarkGrey</material>
  </gazebo>
  <gazebo reference="arm_2_link">
    <mu1>0.9</mu1>
    <mu2>0.9</mu2>
    <material>Gazebo/DarkGrey</material>
  </gazebo>
  <gazebo reference="arm_3_link">
    <mu1>0.9</mu1>
    <mu2>0.9</mu2>
    <material>Gazebo/DarkGrey</material>
  </gazebo>
  <gazebo reference="arm_4_link">
    <mu1>0.9</mu1>
    <mu2>0.9</mu2>
    <material>Gazebo/DarkGrey</material>
  </gazebo>
  <gazebo reference="arm_1_joint">
    <implicitSpringDamper>1</implicitSpringDamper>
  </gazebo>
  <gazebo reference="arm_2_joint">
    <implicitSpringDamper>1</implicitSpringDamper>
  </gazebo>
  <gazebo reference="arm_3_joint">
    <implicitSpringDamper>1</implicitSpringDamper>
  </gazebo>
  <gazebo reference="arm_4_joint">
    <implicitSpringDamper>1</implicitSpringDamper>
  </gazebo>
  <!-- Wrist-->
  <link name="arm_5_link">
   
    <visual>
      <origin rpy="0 0 0" xyz="0 0 0"/>
      <geometry>
        <mesh filename="package://tiago_description/meshes/arm/arm_5-wrist-2010.stl" scale="1 1 1"/>
      </geometry>
      <material name="LightGrey"/>
    </visual>
    <collision>
      <origin rpy="0 0 0" xyz="0 0 0"/>
      <geometry>
        <mesh filename="package://tiago_description/meshes/arm/arm_5_collision-wrist-2010.dae" scale="1 1 1"/>
      </geometry>
    </collision>
  </link>
  <joint name="arm_5_joint" type="revolute">
    <parent link="arm_4_link"/>
    <child link="arm_5_link"/>
    <origin rpy="1.5707963267948966 -1.5707963267948966 -1.5707963267948966" xyz="-0.162 0.02 0.027"/>
    <axis xyz="0 0 1"/>
    <limit effort="3" lower="-2.0943951023931953" upper="2.0943951023931953" velocity="1.95"/>
    <dynamics damping="1.0" friction="1.0"/>
    <safety_controller k_position="20" k_velocity="20" soft_lower_limit="-2.0743951023931952" soft_upper_limit="2.0743951023931952"/>
  </joint>
  <link name="arm_6_link">
   
    <visual>
      <origin rpy="0 0 0" xyz="0 0 0"/>
      <geometry>
        <mesh filename="package://tiago_description/meshes/arm/arm_6-wrist-2010.stl" scale="1 1 1"/>
      </geometry>
      <material name="LightGrey"/>
    </visual>
    <collision>
      <origin rpy="0 0 0" xyz="0 0 0"/>
      <geometry>
        <mesh filename="package://tiago_description/meshes/arm/arm_6_collision-wrist-2010.dae" scale="1 1 1"/>
      </geometry>
    </collision>
  </link>
  <joint name="arm_6_joint" type="revolute">
    <parent link="arm_5_link"/>
    <child link="arm_6_link"/>
    <origin rpy="0.0 -1.5707963267948966 -1.5707963267948966" xyz="0 0 0.15"/>
    <axis xyz="0 0 1"/>
    <limit effort="6.6" lower="-1.413716694115407" upper="1.413716694115407" velocity="1.76"/>
    <dynamics damping="1.0" friction="1.0"/>
    <safety_controller k_position="20" k_velocity="20" soft_lower_limit="-1.3937166941154069" soft_upper_limit="1.3937166941154069"/>
  </joint>
  <link name="arm_7_link">
   
  </link>
  <joint name="arm_7_joint" type="revolute">
    <parent link="arm_6_link"/>
    <child link="arm_7_link"/>
    <origin rpy="1.5707963267948966 0.0 1.5707963267948966" xyz="0 0 0"/>
    <axis xyz="0 0 1"/>
    <limit effort="6.6" lower="-2.0943951023931953" upper="2.0943951023931953" velocity="1.76"/>
    <dynamics damping="1.0" friction="1.0"/>
    <safety_controller k_position="20" k_velocity="20" soft_lower_limit="-2.0743951023931952" soft_upper_limit="2.0743951023931952"/>
  </joint>
  <gazebo reference="arm_5_link">
    <mu1>0.9</mu1>
    <mu2>0.9</mu2>
  </gazebo>
  <gazebo reference="arm_6_link">
    <mu1>0.9</mu1>
    <mu2>0.9</mu2>
  </gazebo>
  <gazebo reference="arm_7_link">
    <mu1>0.9</mu1>
    <mu2>0.9</mu2>
  </gazebo>
  <gazebo reference="arm_5_joint">
    <implicitSpringDamper>1</implicitSpringDamper>
  </gazebo>
  <gazebo reference="arm_6_joint">
    <implicitSpringDamper>1</implicitSpringDamper>
  </gazebo>
  <gazebo reference="arm_7_joint">
    <implicitSpringDamper>1</implicitSpringDamper>
    <provideFeedback>1</provideFeedback>
  </gazebo>
  <!-- Tool -->
  <link name="arm_tool_link">
   
    <visual>
      <origin rpy="0 1.5707963267948966 0" xyz="0.001 0 0"/>
      <geometry>
        <cylinder length="0.005" radius="0.005"/>
      </geometry>
      <material name="LightGrey"/>
    </visual>
    <collision>
      <origin rpy="0 1.5707963267948966 0" xyz="0.001 0 0"/>
      <geometry>
        <cylinder length="0.005" radius="0.005"/>
      </geometry>
    </collision>
  </link>
  <joint name="arm_tool_joint" type="fixed">
    <parent link="arm_7_link"/>
    <child link="arm_tool_link"/>
    <origin rpy="1.5707963267948966 -1.5707963267948966 3.141592653589793" xyz="0 0 0.046"/>
  </joint>
  <!-- FT sensor-->
 
  <!-- FT tool -->
  
  <!-- Tool Link -->
  
 
  <!-- Custom -->
  <!--xacro:if value="${end_effector == 'custom' and not tiago_dual}">
    <xacro:include filename="$(find custom_ee_description)/urdf/end-effector.urdf.xacro" />
      <xacro:end_effector parent="${parent}">
        <origin xyz="0.01 0 0" rpy="${90*deg_to_rad} ${90*deg_to_rad} ${-90*deg_to_rad}"/>
      </xacro:end_effector>
    </xacro:if-->
  <!-- Custom dual-->
  <!--xacro:if value="${end_effector == 'custom' and tiago_dual}">
      <xacro:if value="${reflect == 1}"-->
  <!-- If right -->
  <!--xacro:include filename="$(find custom_dual_ee_description)/urdf/end-effector-right.urdf.xacro" />
    <xacro:end_effector_right parent="${parent}">
      <origin xyz="0.01 0 0" rpy="${90*deg_to_rad} ${90*deg_to_rad} ${-90*deg_to_rad}"/>
    </xacro:end_effector_right>
    </xacro:if>
    <xacro:if value="${reflect == -1}"-->
  <!-- If left -->
  <!--xacro:include filename="$(find custom_dual_ee_description)/urdf/end-effector-left.urdf.xacro" />
    <xacro:end_effector_left parent="${parent}">
      <origin xyz="0.01 0 0" rpy="${90*deg_to_rad} ${90*deg_to_rad} ${-90*deg_to_rad}"/>
    </xacro:end_effector_left>
    </xacro:if>
  </xacro:if-->
  
  
  <!-- ROS 2 control config-->
  <ros2_control name="ros2_control_tiago_system" type="system">
    <!-- Execution env config -->
    <hardware>
      <plugin>robot_control/RobotControl</plugin>
    </hardware>
    <joint name="wheel_right_joint">
      <command_interface name="velocity">
        <param name="min">-1</param>
        <param name="max">1</param>
      </command_interface>
      <state_interface name="position"/>
    </joint>
    <transmission name="wheel_right_trans">
      <plugin>transmission_interface/SimpleTransmission</plugin>
      <actuator name="wheel_right_actuator" role="actuator1"/>
      <joint name="wheel_right_joint" role="joint1">
        <mechanical_reduction>1.0</mechanical_reduction>
      </joint>
    </transmission>
    <joint name="wheel_left_joint">
      <command_interface name="velocity">
        <param name="min">-1</param>
        <param name="max">1</param>
      </command_interface>
      <state_interface name="position"/>
    </joint>
    <transmission name="wheel_left_trans">
      <plugin>transmission_interface/SimpleTransmission</plugin>
      <actuator name="wheel_left_actuator" role="actuator1"/>
      <joint name="wheel_left_joint" role="joint1">
        <mechanical_reduction>1.0</mechanical_reduction>
      </joint>
    </transmission>
    <joint name="torso_lift_joint">
      <command_interface name="position"/>
      <state_interface name="position"/>
      <state_interface name="velocity"/>
      <state_interface name="effort"/>
    </joint>
    <transmission name="torso_lift_trans">
      <plugin>transmission_interface/SimpleTransmission</plugin>
      <actuator name="torso_lift_actuator" role="actuator1"/>
      <joint name="torso_lift_joint" role="joint1">
        <mechanical_reduction>1.0</mechanical_reduction>
        <offset>0.0</offset>
      </joint>
    </transmission>
    <joint name="arm_1_joint">
      <command_interface name="position"/>
      <command_interface name="velocity"/>
      <command_interface name="effort"/>
      <state_interface name="position"/>
      <state_interface name="velocity"/>
      <state_interface name="effort"/>
    </joint>
    <transmission name="arm_1_trans">
      <plugin>transmission_interface/SimpleTransmission</plugin>
      <actuator name="arm_1_actuator" role="actuator1"/>
      <joint name="arm_1_joint" role="joint1">
        <mechanical_reduction>1.0</mechanical_reduction>
        <offset>0.0</offset>
      </joint>
    </transmission>
    <joint name="arm_2_joint">
      <command_interface name="position"/>
      <command_interface name="velocity"/>
      <command_interface name="effort"/>
      <state_interface name="position"/>
      <state_interface name="velocity"/>
      <state_interface name="effort"/>
    </joint>
    <transmission name="arm_2_trans">
      <plugin>transmission_interface/SimpleTransmission</plugin>
      <actuator name="arm_2_actuator" role="actuator1"/>
      <joint name="arm_2_joint" role="joint1">
        <mechanical_reduction>1.0</mechanical_reduction>
        <offset>0.0</offset>
      </joint>
    </transmission>
    <joint name="arm_3_joint">
      <command_interface name="position"/>
      <command_interface name="velocity"/>
      <command_interface name="effort"/>
      <state_interface name="position"/>
      <state_interface name="velocity"/>
      <state_interface name="effort"/>
    </joint>
    <transmission name="arm_3_trans">
      <plugin>transmission_interface/SimpleTransmission</plugin>
      <actuator name="arm_3_actuator" role="actuator1"/>
      <joint name="arm_3_joint" role="joint1">
        <mechanical_reduction>1.0</mechanical_reduction>
        <offset>0.0</offset>
      </joint>
    </transmission>
    <joint name="arm_4_joint">
      <command_interface name="position"/>
      <command_interface name="velocity"/>
      <command_interface name="effort"/>
      <state_interface name="position"/>
      <state_interface name="velocity"/>
      <state_interface name="effort"/>
    </joint>
    <transmission name="arm_4_trans">
      <plugin>transmission_interface/SimpleTransmission</plugin>
      <actuator name="arm_4_actuator" role="actuator1"/>
      <joint name="arm_4_joint" role="joint1">
        <mechanical_reduction>1.0</mechanical_reduction>
        <offset>0.0</offset>
      </joint>
    </transmission>
    <joint name="arm_5_joint">
      <command_interface name="position"/>
      <command_interface name="velocity"/>
      <command_interface name="effort"/>
      <state_interface name="position"/>
      <state_interface name="velocity"/>
      <state_interface name="effort"/>
    </joint>
    <transmission name="arm_5_trans">
      <plugin>transmission_interface/SimpleTransmission</plugin>
      <actuator name="arm_5_actuator" role="actuator1"/>
      <joint name="arm_5_joint" role="joint1">
        <mechanical_reduction>1.0</mechanical_reduction>
        <offset>0.0</offset>
      </joint>
    </transmission>
    <joint name="arm_6_joint">
      <command_interface name="position"/>
      <command_interface name="velocity"/>
      <command_interface name="effort"/>
      <state_interface name="position"/>
      <state_interface name="velocity"/>
      <state_interface name="effort"/>
    </joint>
    <joint name="arm_7_joint">
      <command_interface name="position"/>
      <command_interface name="velocity"/>
      <command_interface name="effort"/>
      <state_interface name="position"/>
      <state_interface name="velocity"/>
      <state_interface name="effort"/>
    </joint>
    <transmission name="arm_6_arm_7_wrist_trans">
      <plugin>transmission_interface/DifferentialTransmission</plugin>
      <actuator name="arm_6_actuator" role="actuator1">
        <mechanical_reduction>-1.0</mechanical_reduction>
      </actuator>
      <actuator name="arm_7_actuator" role="actuator2">
        <mechanical_reduction>1.0</mechanical_reduction>
      </actuator>
      <joint name="arm_6_joint" role="joint1">
        <mechanical_reduction>1.0</mechanical_reduction>
        <offset>0.0</offset>
      </joint>
      <joint name="arm_7_joint" role="joint2">
        <mechanical_reduction>-1.0</mechanical_reduction>
        <offset>0.0</offset>
      </joint>
    </transmission>
    <sensor name="wrist_ft_sensor">
      <state_interface name="force.x"/>
      <state_interface name="force.y"/>
      <state_interface name="force.z"/>
      <state_interface name="torque.x"/>
      <state_interface name="torque.y"/>
      <state_interface name="torque.z"/>
    </sensor>
   
  </ros2_control>
</robot>
