<sdf version='1.7'>
  <model name='tiago'>
    <link name='base_footprint'>
      <inertial>
        <pose>-0.006735 -0.001027 0.169511 0 -0 0</pose>
        <mass>63.4105</mass>
        <inertia>
          <ixx>4.28569</ixx>
          <ixy>0.000542419</ixy>
          <ixz>0.1274</ixz>
          <iyy>4.37559</iyy>
          <iyz>0.0168147</iyz>
          <izz>2.69046</izz>
        </inertia>
      </inertial>
      <collision name='base_footprint_fixed_joint_lump__base_link_collision'>
        <pose>0 0 0.0985 0 -0 0</pose>
        <geometry>
          <mesh>
            <scale>1 1 1</scale>
            <uri>model://pmb2_description/meshes/base/high_resolution/base_collision.stl</uri>
          </mesh>
        </geometry>
        <surface>
          <contact>
            <ode/>
          </contact>
          <friction>
            <ode/>
          </friction>
        </surface>
      </collision>
      <collision name='base_footprint_fixed_joint_lump__base_antenna_left_link_collision_1'>
        <pose>-0.201 0.1062 0.3785 0 -0 0</pose>
        <geometry>
          <cylinder>
            <length>0.17</length>
            <radius>0.005</radius>
          </cylinder>
        </geometry>
        <surface>
          <contact>
            <ode/>
          </contact>
          <friction>
            <ode/>
          </friction>
        </surface>
      </collision>
      <collision name='base_footprint_fixed_joint_lump__base_antenna_right_link_collision_2'>
        <pose>-0.201 -0.1062 0.3785 0 -0 0</pose>
        <geometry>
          <cylinder>
            <length>0.17</length>
            <radius>0.005</radius>
          </cylinder>
        </geometry>
        <surface>
          <contact>
            <ode/>
          </contact>
          <friction>
            <ode/>
          </friction>
        </surface>
      </collision>
      <collision name='base_footprint_fixed_joint_lump__caster_back_left_2_link_collision_3'>
        <pose>-0.1895 0.102 0.025 -1.5708 0 0</pose>
        <geometry>
          <sphere>
            <radius>0.025</radius>
          </sphere>
        </geometry>
        <surface>
          <contact>
            <ode>
              <kp>1e+06</kp>
              <kd>10000</kd>
            </ode>
          </contact>
          <friction>
            <ode>
              <mu>0</mu>
              <mu2>0</mu2>
            </ode>
          </friction>
        </surface>
      </collision>
      <collision name='base_footprint_fixed_joint_lump__caster_back_right_2_link_collision_4'>
        <pose>-0.1895 -0.102 0.025 -1.5708 0 0</pose>
        <geometry>
          <sphere>
            <radius>0.025</radius>
          </sphere>
        </geometry>
        <surface>
          <contact>
            <ode>
              <kp>1e+06</kp>
              <kd>10000</kd>
            </ode>
          </contact>
          <friction>
            <ode>
              <mu>0</mu>
              <mu2>0</mu2>
            </ode>
          </friction>
        </surface>
      </collision>
      <collision name='base_footprint_fixed_joint_lump__caster_front_left_2_link_collision_5'>
        <pose>0.1535 0.102 0.025 -1.5708 0 0</pose>
        <geometry>
          <sphere>
            <radius>0.025</radius>
          </sphere>
        </geometry>
        <surface>
          <contact>
            <ode>
              <kp>1e+06</kp>
              <kd>10000</kd>
            </ode>
          </contact>
          <friction>
            <ode>
              <mu>0</mu>
              <mu2>0</mu2>
            </ode>
          </friction>
        </surface>
      </collision>
      <collision name='base_footprint_fixed_joint_lump__caster_front_right_2_link_collision_6'>
        <pose>0.1535 -0.102 0.025 -1.5708 0 0</pose>
        <geometry>
          <sphere>
            <radius>0.025</radius>
          </sphere>
        </geometry>
        <surface>
          <contact>
            <ode>
              <kp>1e+06</kp>
              <kd>10000</kd>
            </ode>
          </contact>
          <friction>
            <ode>
              <mu>0</mu>
              <mu2>0</mu2>
            </ode>
          </friction>
        </surface>
      </collision>
      <collision name='base_footprint_fixed_joint_lump__torso_fixed_column_link_collision_7'>
        <pose>-0.062 0 0.5685 0 -0 0</pose>
        <geometry>
          <box>
            <size>0.23 0.23 0.55</size>
          </box>
        </geometry>
        <surface>
          <contact>
            <ode/>
          </contact>
          <friction>
            <ode/>
          </friction>
        </surface>
      </collision>
      <collision name='base_footprint_fixed_joint_lump__torso_fixed_link_collision_8'>
        <pose>0.023 0 0.3115 0 -0 0</pose>
        <geometry>
          <box>
            <size>0.4 0.25 0.04</size>
          </box>
        </geometry>
      </collision>
      <collision name='base_footprint_fixed_joint_lump__torso_fixed_link_collision_9'>
        <pose>-0.062 0 0.3415 0 -0 0</pose>
        <geometry>
          <box>
            <size>0.25 0.25 0.1</size>
          </box>
        </geometry>
      </collision>
      <visual name='base_footprint_fixed_joint_lump__base_link_visual'>
        <pose>0 0 0.0985 0 -0 0</pose>
        <geometry>
          <mesh>
            <scale>1 1 1</scale>
            <uri>model://pmb2_description/meshes/base/base.stl</uri>
          </mesh>
        </geometry>
        <material>
          <script>
            <name>Gazebo/White</name>
            <uri>file://media/materials/scripts/gazebo.material</uri>
          </script>
        </material>
      </visual>
      <visual name='base_footprint_fixed_joint_lump__base_antenna_left_link_visual_1'>
        <pose>-0.201 0.1062 0.2935 0 -0 0</pose>
        <geometry>
          <mesh>
            <scale>1 1 1</scale>
            <uri>model://pmb2_description/meshes/objects/antenna.stl</uri>
          </mesh>
        </geometry>
        <material>
          <script>
            <name>Gazebo/Black</name>
            <uri>file://media/materials/scripts/gazebo.material</uri>
          </script>
        </material>
      </visual>
      <visual name='base_footprint_fixed_joint_lump__base_antenna_right_link_visual_2'>
        <pose>-0.201 -0.1062 0.2935 0 -0 0</pose>
        <geometry>
          <mesh>
            <scale>1 1 1</scale>
            <uri>model://pmb2_description/meshes/objects/antenna.stl</uri>
          </mesh>
        </geometry>
        <material>
          <script>
            <name>Gazebo/Black</name>
            <uri>file://media/materials/scripts/gazebo.material</uri>
          </script>
        </material>
      </visual>
      <visual name='base_footprint_fixed_joint_lump__base_laser_link_visual_3'>
        <pose>0.202 0 0.0945 0 -0 0</pose>
        <geometry>
          <mesh>
            <scale>1 1 1</scale>
            <uri>model://pmb2_description/meshes/sensors/sick_tim551.stl</uri>
          </mesh>
        </geometry>
        <material>
          <script>
            <name>Gazebo/DarkGrey</name>
            <uri>file://media/materials/scripts/gazebo.material</uri>
          </script>
        </material>
      </visual>
      <visual name='base_footprint_fixed_joint_lump__base_sonar_01_link_visual_4'>
        <pose>-0.183 -0.183 0.2715 0 0 -2.35619</pose>
        <geometry>
          <mesh>
            <scale>1 1 1</scale>
            <uri>model://pmb2_description/meshes/sensors/srf05.stl</uri>
          </mesh>
        </geometry>
        <material>
          <script>
            <name>Gazebo/DarkGrey</name>
            <uri>file://media/materials/scripts/gazebo.material</uri>
          </script>
        </material>
      </visual>
      <visual name='base_footprint_fixed_joint_lump__base_sonar_02_link_visual_5'>
        <pose>-0.259 0 0.2715 0 -0 3.14159</pose>
        <geometry>
          <mesh>
            <scale>1 1 1</scale>
            <uri>model://pmb2_description/meshes/sensors/srf05.stl</uri>
          </mesh>
        </geometry>
        <material>
          <script>
            <name>Gazebo/DarkGrey</name>
            <uri>file://media/materials/scripts/gazebo.material</uri>
          </script>
        </material>
      </visual>
      <visual name='base_footprint_fixed_joint_lump__base_sonar_03_link_visual_6'>
        <pose>-0.183 0.183 0.2715 0 -0 2.35619</pose>
        <geometry>
          <mesh>
            <scale>1 1 1</scale>
            <uri>model://pmb2_description/meshes/sensors/srf05.stl</uri>
          </mesh>
        </geometry>
        <material>
          <script>
            <name>Gazebo/DarkGrey</name>
            <uri>file://media/materials/scripts/gazebo.material</uri>
          </script>
        </material>
      </visual>
      <visual name='base_footprint_fixed_joint_lump__caster_back_left_1_link_visual_7'>
        <pose>-0.1735 0.102 0.065 0 -0 0</pose>
        <geometry>
          <mesh>
            <scale>1 1 1</scale>
            <uri>model://pmb2_description/meshes/wheels/caster_1.stl</uri>
          </mesh>
        </geometry>
        <material>
          <script>
            <name>Gazebo/DarkGrey</name>
            <uri>file://media/materials/scripts/gazebo.material</uri>
          </script>
        </material>
      </visual>
      <visual name='base_footprint_fixed_joint_lump__caster_back_left_2_link_visual_8'>
        <pose>-0.1895 0.102 0.025 -1.5708 0 0</pose>
        <geometry>
          <mesh>
            <scale>1 1 1</scale>
            <uri>model://pmb2_description/meshes/wheels/caster_2.stl</uri>
          </mesh>
        </geometry>
        <material>
          <script>
            <name>Gazebo/DarkGrey</name>
            <uri>file://media/materials/scripts/gazebo.material</uri>
          </script>
        </material>
      </visual>
      <visual name='base_footprint_fixed_joint_lump__caster_back_right_1_link_visual_9'>
        <pose>-0.1735 -0.102 0.065 0 -0 0</pose>
        <geometry>
          <mesh>
            <scale>1 1 1</scale>
            <uri>model://pmb2_description/meshes/wheels/caster_1.stl</uri>
          </mesh>
        </geometry>
        <material>
          <script>
            <name>Gazebo/DarkGrey</name>
            <uri>file://media/materials/scripts/gazebo.material</uri>
          </script>
        </material>
      </visual>
      <visual name='base_footprint_fixed_joint_lump__caster_back_right_2_link_visual_10'>
        <pose>-0.1895 -0.102 0.025 -1.5708 0 0</pose>
        <geometry>
          <mesh>
            <scale>1 1 1</scale>
            <uri>model://pmb2_description/meshes/wheels/caster_2.stl</uri>
          </mesh>
        </geometry>
        <material>
          <script>
            <name>Gazebo/DarkGrey</name>
            <uri>file://media/materials/scripts/gazebo.material</uri>
          </script>
        </material>
      </visual>
      <visual name='base_footprint_fixed_joint_lump__caster_front_left_1_link_visual_11'>
        <pose>0.1695 0.102 0.065 0 -0 0</pose>
        <geometry>
          <mesh>
            <scale>1 1 1</scale>
            <uri>model://pmb2_description/meshes/wheels/caster_1.stl</uri>
          </mesh>
        </geometry>
        <material>
          <script>
            <name>Gazebo/DarkGrey</name>
            <uri>file://media/materials/scripts/gazebo.material</uri>
          </script>
        </material>
      </visual>
      <visual name='base_footprint_fixed_joint_lump__caster_front_left_2_link_visual_12'>
        <pose>0.1535 0.102 0.025 -1.5708 0 0</pose>
        <geometry>
          <mesh>
            <scale>1 1 1</scale>
            <uri>model://pmb2_description/meshes/wheels/caster_2.stl</uri>
          </mesh>
        </geometry>
        <material>
          <script>
            <name>Gazebo/DarkGrey</name>
            <uri>file://media/materials/scripts/gazebo.material</uri>
          </script>
        </material>
      </visual>
      <visual name='base_footprint_fixed_joint_lump__caster_front_right_1_link_visual_13'>
        <pose>0.1695 -0.102 0.065 0 -0 0</pose>
        <geometry>
          <mesh>
            <scale>1 1 1</scale>
            <uri>model://pmb2_description/meshes/wheels/caster_1.stl</uri>
          </mesh>
        </geometry>
        <material>
          <script>
            <name>Gazebo/DarkGrey</name>
            <uri>file://media/materials/scripts/gazebo.material</uri>
          </script>
        </material>
      </visual>
      <visual name='base_footprint_fixed_joint_lump__caster_front_right_2_link_visual_14'>
        <pose>0.1535 -0.102 0.025 -1.5708 0 0</pose>
        <geometry>
          <mesh>
            <scale>1 1 1</scale>
            <uri>model://pmb2_description/meshes/wheels/caster_2.stl</uri>
          </mesh>
        </geometry>
        <material>
          <script>
            <name>Gazebo/DarkGrey</name>
            <uri>file://media/materials/scripts/gazebo.material</uri>
          </script>
        </material>
      </visual>
      <visual name='base_footprint_fixed_joint_lump__torso_fixed_column_link_visual_15'>
        <pose>-0.062 0 0.5685 0 -0 0</pose>
        <geometry>
          <box>
            <size>0.18 0.2 0.55</size>
          </box>
        </geometry>
        <material>
          <script>
            <name>Gazebo/DarkGrey</name>
            <uri>file://media/materials/scripts/gazebo.material</uri>
          </script>
        </material>
      </visual>
      <visual name='base_footprint_fixed_joint_lump__torso_fixed_link_visual_16'>
        <pose>-0.062 0 0.2915 0 -0 0</pose>
        <geometry>
          <mesh>
            <scale>1 1 1</scale>
            <uri>model://tiago_description/meshes/torso/torso_fix.stl</uri>
          </mesh>
        </geometry>
      </visual>
      <visual name='base_footprint_fixed_joint_lump__base_cover_link_visual_17'>
        <pose>0 0 0.13 0 -0 0</pose>
        <geometry>
          <mesh>
            <scale>1 1 1</scale>
            <uri>model://pmb2_description/meshes/base/base_ring.stl</uri>
          </mesh>
        </geometry>
        <material>
          <script>
            <name>Gazebo/Orange</name>
            <uri>file://media/materials/scripts/gazebo.material</uri>
          </script>
        </material>
      </visual>
      <sensor name='base_imu_sensor' type='imu'>
        <always_on>1</always_on>
        <update_rate>100</update_rate>
        <imu>
          <noise>
            <type>gaussian</type>
            <rate>
              <mean>0.0</mean>
              <stddev>2e-4</stddev>
              <bias_mean>0.0000075</bias_mean>
              <bias_stddev>0.0000008</bias_stddev>
            </rate>
            <accel>
              <mean>0.0</mean>
              <stddev>1.7e-2</stddev>
              <bias_mean>0.1</bias_mean>
              <bias_stddev>0.001</bias_stddev>
            </accel>
          </noise>
        </imu>
        <plugin name='base_imu' filename='libgazebo_ros_imu_sensor.so'>
          <ros>
            <remapping>~/out:=base_imu</remapping>
          </ros>
        </plugin>
        <pose>0.10171 0 0.21132 0 0 -1.5708</pose>
      </sensor>
      <sensor name='base_laser' type='ray'>
        <update_rate>10</update_rate>
        <visualize>1</visualize>
        <ray>
          <scan>
            <horizontal>
              <samples>666</samples>
              <resolution>1</resolution>
              <min_angle>-1.91986</min_angle>
              <max_angle>1.91986</max_angle>
            </horizontal>
          </scan>
          <range>
            <min>0.05</min>
            <max>25</max>
            <resolution>0.001</resolution>
          </range>
          <noise>
            <type>gaussian</type>
            <mean>0</mean>
            <stddev>0.01</stddev>
          </noise>
        </ray>
        <plugin name='base_laser' filename='libgazebo_ros_ray_sensor.so'>
          <ros>
            <remapping>~/out:=scan_raw</remapping>
          </ros>
          <output_type>sensor_msgs/LaserScan</output_type>
          <frame_name>base_laser_link</frame_name>
        </plugin>
        <pose>0.202 0 0.0945 0 -0 0</pose>
      </sensor>
      <sensor name='base_sonar_01' type='ray'>
        <update_rate>5</update_rate>
        <visualize>0</visualize>
        <ray>
          <scan>
            <horizontal>
              <samples>5</samples>
              <resolution>1</resolution>
              <min_angle>-0.25</min_angle>
              <max_angle>0.25</max_angle>
            </horizontal>
            <vertical>
              <samples>5</samples>
              <resolution>1</resolution>
              <min_angle>-0.25</min_angle>
              <max_angle>0.25</max_angle>
            </vertical>
          </scan>
          <range>
            <min>0.02</min>
            <max>1</max>
            <resolution>0.01</resolution>
          </range>
          <noise>
            <type>gaussian</type>
            <mean>0</mean>
            <stddev>0.005</stddev>
          </noise>
        </ray>
        <plugin name='base_sonar_01_gazebo_ros_range' filename='libgazebo_ros_ray_sensor.so'>
          <ros>
            <namespace/>
            <remapping>~/out:=sonar_base</remapping>
          </ros>
          <output_type>sensor_msgs/Range</output_type>
          <radiation_type>ultrasound</radiation_type>
          <frame_name>base_sonar_01_link</frame_name>
        </plugin>
        <pose>-0.183 -0.183 0.2715 0 -0 -2.35619</pose>
      </sensor>
      <sensor name='base_sonar_02' type='ray'>
        <update_rate>5</update_rate>
        <visualize>0</visualize>
        <ray>
          <scan>
            <horizontal>
              <samples>5</samples>
              <resolution>1</resolution>
              <min_angle>-0.25</min_angle>
              <max_angle>0.25</max_angle>
            </horizontal>
            <vertical>
              <samples>5</samples>
              <resolution>1</resolution>
              <min_angle>-0.25</min_angle>
              <max_angle>0.25</max_angle>
            </vertical>
          </scan>
          <range>
            <min>0.02</min>
            <max>1</max>
            <resolution>0.01</resolution>
          </range>
          <noise>
            <type>gaussian</type>
            <mean>0</mean>
            <stddev>0.005</stddev>
          </noise>
        </ray>
        <plugin name='base_sonar_02_gazebo_ros_range' filename='libgazebo_ros_ray_sensor.so'>
          <ros>
            <namespace/>
            <remapping>~/out:=sonar_base</remapping>
          </ros>
          <output_type>sensor_msgs/Range</output_type>
          <radiation_type>ultrasound</radiation_type>
          <frame_name>base_sonar_02_link</frame_name>
        </plugin>
        <pose>-0.259 0 0.2715 0 -0 3.14159</pose>
      </sensor>
      <sensor name='base_sonar_03' type='ray'>
        <update_rate>5</update_rate>
        <visualize>0</visualize>
        <ray>
          <scan>
            <horizontal>
              <samples>5</samples>
              <resolution>1</resolution>
              <min_angle>-0.25</min_angle>
              <max_angle>0.25</max_angle>
            </horizontal>
            <vertical>
              <samples>5</samples>
              <resolution>1</resolution>
              <min_angle>-0.25</min_angle>
              <max_angle>0.25</max_angle>
            </vertical>
          </scan>
          <range>
            <min>0.02</min>
            <max>1</max>
            <resolution>0.01</resolution>
          </range>
          <noise>
            <type>gaussian</type>
            <mean>0</mean>
            <stddev>0.005</stddev>
          </noise>
        </ray>
        <plugin name='base_sonar_03_gazebo_ros_range' filename='libgazebo_ros_ray_sensor.so'>
          <ros>
            <namespace/>
            <remapping>~/out:=sonar_base</remapping>
          </ros>
          <output_type>sensor_msgs/Range</output_type>
          <radiation_type>ultrasound</radiation_type>
          <frame_name>base_sonar_03_link</frame_name>
        </plugin>
        <pose>-0.183 0.183 0.2715 0 -0 2.35619</pose>
      </sensor>
      <max_vel>1.0</max_vel>
      <min_depth>0.005</min_depth>
      <max_vel>1.0</max_vel>
      <min_depth>0.005</min_depth>
      <max_vel>1.0</max_vel>
      <min_depth>0.005</min_depth>
      <max_vel>1.0</max_vel>
      <min_depth>0.005</min_depth>
      <max_vel>1.0</max_vel>
      <min_depth>0.005</min_depth>
      <max_vel>1.0</max_vel>
      <min_depth>0.005</min_depth>
      <max_vel>1.0</max_vel>
      <min_depth>0.005</min_depth>
      <max_vel>1.0</max_vel>
      <min_depth>0.005</min_depth>
    </link>
    <joint name='wheel_left_joint' type='revolute'>
      <pose relative_to='base_footprint'>0 0.2022 0.0985 -1.5708 0 0</pose>
      <parent>base_footprint</parent>
      <child>wheel_left_link</child>
      <axis>
        <xyz>0 0 1</xyz>
        <limit>
          <effort>6</effort>
          <velocity>10.1523</velocity>
          <lower>-1e+16</lower>
          <upper>1e+16</upper>
        </limit>
        <dynamics>
          <damping>1</damping>
          <friction>2</friction>
          <spring_reference>0</spring_reference>
          <spring_stiffness>0</spring_stiffness>
        </dynamics>
      </axis>
    </joint>
    <link name='wheel_left_link'>
      <pose relative_to='wheel_left_joint'>0 0 0 0 -0 0</pose>
      <inertial>
        <pose>0 0 0.00207 0 -0 0</pose>
        <mass>1.82362</mass>
        <inertia>
          <ixx>0.00499743</ixx>
          <ixy>-4.464e-08</ixy>
          <ixz>-2.245e-08</ixz>
          <iyy>0.00499742</iyy>
          <iyz>1.64e-09</iyz>
          <izz>0.0083924</izz>
        </inertia>
      </inertial>
      <collision name='wheel_left_link_collision'>
        <pose>0 0 0 0 -0 0</pose>
        <geometry>
          <sphere>
            <radius>0.0985</radius>
          </sphere>
        </geometry>
        <surface>
          <contact>
            <ode>
              <kp>1e+06</kp>
              <kd>100</kd>
            </ode>
          </contact>
          <friction>
            <ode/>
          </friction>
        </surface>
      </collision>
      <visual name='wheel_left_link_visual'>
        <pose>0 0 0 -3.14159 0 0</pose>
        <geometry>
          <mesh>
            <scale>1 1 1</scale>
            <uri>model://pmb2_description/meshes/wheels/wheel.stl</uri>
          </mesh>
        </geometry>
        <material>
          <script>
            <name>Gazebo/DarkGrey</name>
            <uri>file://media/materials/scripts/gazebo.material</uri>
          </script>
        </material>
      </visual>
      <friction>
        <ode>
          <mu>1.0</mu>
          <mu2>1.0</mu2>
        </ode>
      </friction>
      <max_vel>1.0</max_vel>
      <min_depth>0.002</min_depth>
    </link>
    <joint name='wheel_right_joint' type='revolute'>
      <pose relative_to='base_footprint'>0 -0.2022 0.0985 -1.5708 0 0</pose>
      <parent>base_footprint</parent>
      <child>wheel_right_link</child>
      <axis>
        <xyz>0 0 1</xyz>
        <limit>
          <effort>6</effort>
          <velocity>10.1523</velocity>
          <lower>-1e+16</lower>
          <upper>1e+16</upper>
        </limit>
        <dynamics>
          <damping>1</damping>
          <friction>2</friction>
          <spring_reference>0</spring_reference>
          <spring_stiffness>0</spring_stiffness>
        </dynamics>
      </axis>
    </joint>
    <link name='wheel_right_link'>
      <pose relative_to='wheel_right_joint'>0 0 0 0 -0 0</pose>
      <inertial>
        <pose>0 0 -0.00207 0 -0 0</pose>
        <mass>1.82362</mass>
        <inertia>
          <ixx>0.00499743</ixx>
          <ixy>4.464e-08</ixy>
          <ixz>-2.245e-08</ixz>
          <iyy>0.00499742</iyy>
          <iyz>-1.64e-09</iyz>
          <izz>0.0083924</izz>
        </inertia>
      </inertial>
      <collision name='wheel_right_link_collision'>
        <pose>0 0 0 0 -0 0</pose>
        <geometry>
          <sphere>
            <radius>0.0985</radius>
          </sphere>
        </geometry>
        <surface>
          <contact>
            <ode>
              <kp>1e+06</kp>
              <kd>100</kd>
            </ode>
          </contact>
          <friction>
            <ode/>
          </friction>
        </surface>
      </collision>
      <visual name='wheel_right_link_visual'>
        <pose>0 0 0 0 -0 0</pose>
        <geometry>
          <mesh>
            <scale>1 1 1</scale>
            <uri>model://pmb2_description/meshes/wheels/wheel.stl</uri>
          </mesh>
        </geometry>
        <material>
          <script>
            <name>Gazebo/DarkGrey</name>
            <uri>file://media/materials/scripts/gazebo.material</uri>
          </script>
        </material>
      </visual>
      <friction>
        <ode>
          <mu>1.0</mu>
          <mu2>1.0</mu2>
        </ode>
      </friction>
      <max_vel>1.0</max_vel>
      <min_depth>0.002</min_depth>
    </link>
    <joint name='torso_lift_joint' type='prismatic'>
      <pose relative_to='base_footprint'>-0.062 0 0.8885 0 -0 0</pose>
      <parent>base_footprint</parent>
      <child>torso_lift_link</child>
      <axis>
        <xyz>0 0 1</xyz>
        <limit>
          <lower>0</lower>
          <upper>0.35</upper>
          <effort>2000</effort>
          <velocity>0.07</velocity>
        </limit>
        <dynamics>
          <damping>1000</damping>
          <friction>0</friction>
          <spring_reference>0</spring_reference>
          <spring_stiffness>0</spring_stiffness>
        </dynamics>
      </axis>
    </joint>
    <link name='torso_lift_link'>
      <pose relative_to='torso_lift_joint'>0 0 0 0 -0 0</pose>
      <inertial>
        <pose>0.04361 -0.00116 -0.17334 0 -0 0</pose>
        <mass>6.93198</mass>
        <inertia>
          <ixx>0.24487</ixx>
          <ixy>-0.001456</ixy>
          <ixz>-0.009742</ixz>
          <iyy>0.249269</iyy>
          <iyz>0.008281</iyz>
          <izz>0.090395</izz>
        </inertia>
      </inertial>
      <collision name='torso_lift_link_collision'>
        <pose>0 0 0 0 -0 0</pose>
        <geometry>
          <mesh>
            <scale>1 1 1</scale>
            <uri>model://tiago_description/meshes/torso/torso_lift_collision_core.dae</uri>
          </mesh>
        </geometry>
      </collision>
      <collision name='torso_lift_link_collision_1'>
        <pose>0 0 0 0 -0 0</pose>
        <geometry>
          <mesh>
            <scale>1 1 1</scale>
            <uri>model://tiago_description/meshes/torso/torso_lift_collision_shoulder.dae</uri>
          </mesh>
        </geometry>
      </collision>
      <collision name='torso_lift_link_collision_2'>
        <pose>0 0 0 0 -0 0</pose>
        <geometry>
          <mesh>
            <scale>1 1 1</scale>
            <uri>model://tiago_description/meshes/torso/torso_lift_collision_neck.dae</uri>
          </mesh>
        </geometry>
      </collision>
      <visual name='torso_lift_link_visual'>
        <pose>0 0 0 0 -0 0</pose>
        <geometry>
          <mesh>
            <scale>1 1 1</scale>
            <uri>model://tiago_description/meshes/torso/torso_lift_with_arm.stl</uri>
          </mesh>
        </geometry>
      </visual>
    </link>
    <joint name='arm_1_joint' type='revolute'>
      <pose relative_to='torso_lift_link'>0.15505 0.014 -0.151 0 0 -1.5708</pose>
      <parent>torso_lift_link</parent>
      <child>arm_1_link</child>
      <axis>
        <xyz>0 0 1</xyz>
        <limit>
          <lower>0</lower>
          <upper>2.74889</upper>
          <effort>43</effort>
          <velocity>1.95</velocity>
        </limit>
        <dynamics>
          <damping>40</damping>
          <friction>1</friction>
          <spring_reference>0</spring_reference>
          <spring_stiffness>0</spring_stiffness>
        </dynamics>
      </axis>
      <physics>
        <ode>
          <implicit_spring_damper>1</implicit_spring_damper>
          <cfm_damping>1</cfm_damping>
          <limit>
            <cfm>0</cfm>
            <erp>0.2</erp>
          </limit>
        </ode>
      </physics>
    </joint>
    <link name='arm_1_link'>
      <pose relative_to='arm_1_joint'>0 0 0 0 -0 0</pose>
      <inertial>
        <pose>0.061191 -0.022397 -0.012835 0 -0 0</pose>
        <mass>1.56343</mass>
        <inertia>
          <ixx>0.002471</ixx>
          <ixy>-0.001809</ixy>
          <ixz>-0.001202</ixz>
          <iyy>0.006132</iyy>
          <iyz>0.000494</iyz>
          <izz>0.006704</izz>
        </inertia>
      </inertial>
      <collision name='arm_1_link_collision'>
        <pose>0 0 0 0 -0 0</pose>
        <geometry>
          <mesh>
            <scale>1 1 1</scale>
            <uri>model://tiago_description/meshes/arm/arm_1_collision.dae</uri>
          </mesh>
        </geometry>
        <surface>
          <contact>
            <ode/>
          </contact>
          <friction>
            <ode>
              <mu>0.9</mu>
              <mu2>0.9</mu2>
            </ode>
          </friction>
        </surface>
      </collision>
      <visual name='arm_1_link_visual'>
        <pose>0 0 0 0 -0 0</pose>
        <geometry>
          <mesh>
            <scale>1 1 1</scale>
            <uri>model://tiago_description/meshes/arm/arm_1.stl</uri>
          </mesh>
        </geometry>
        <material>
          <script>
            <name>Gazebo/DarkGrey</name>
            <uri>file://media/materials/scripts/gazebo.material</uri>
          </script>
        </material>
      </visual>
    </link>
    <joint name='arm_2_joint' type='revolute'>
      <pose relative_to='arm_1_link'>0.125 0.0195 -0.031 1.5708 -0 0</pose>
      <parent>arm_1_link</parent>
      <child>arm_2_link</child>
      <axis>
        <xyz>0 0 1</xyz>
        <limit>
          <lower>-1.5708</lower>
          <upper>1.09083</upper>
          <effort>43</effort>
          <velocity>1.95</velocity>
        </limit>
        <dynamics>
          <damping>40</damping>
          <friction>1</friction>
          <spring_reference>0</spring_reference>
          <spring_stiffness>0</spring_stiffness>
        </dynamics>
      </axis>
      <physics>
        <ode>
          <implicit_spring_damper>1</implicit_spring_damper>
          <cfm_damping>1</cfm_damping>
          <limit>
            <cfm>0</cfm>
            <erp>0.2</erp>
          </limit>
        </ode>
      </physics>
    </joint>
    <link name='arm_2_link'>
      <pose relative_to='arm_2_joint'>0 0 0 0 -0 0</pose>
      <inertial>
        <pose>0.030432 0.000229 -0.005942 0 -0 0</pose>
        <mass>1.8004</mass>
        <inertia>
          <ixx>0.001809</ixx>
          <ixy>1.5e-05</ixy>
          <ixz>0.000254</ixz>
          <iyy>0.004333</iyy>
          <iyz>1.4e-05</iyz>
          <izz>0.004341</izz>
        </inertia>
      </inertial>
      <collision name='arm_2_link_collision'>
        <pose>0 0 0 0 -0 0</pose>
        <geometry>
          <mesh>
            <scale>1 1 1</scale>
            <uri>model://tiago_description/meshes/arm/arm_2_collision.dae</uri>
          </mesh>
        </geometry>
        <surface>
          <contact>
            <ode/>
          </contact>
          <friction>
            <ode>
              <mu>0.9</mu>
              <mu2>0.9</mu2>
            </ode>
          </friction>
        </surface>
      </collision>
      <visual name='arm_2_link_visual'>
        <pose>0 0 0 0 -0 0</pose>
        <geometry>
          <mesh>
            <scale>1 1 1</scale>
            <uri>model://tiago_description/meshes/arm/arm_2.stl</uri>
          </mesh>
        </geometry>
        <material>
          <script>
            <name>Gazebo/DarkGrey</name>
            <uri>file://media/materials/scripts/gazebo.material</uri>
          </script>
        </material>
      </visual>
    </link>
    <joint name='arm_3_joint' type='revolute'>
      <pose relative_to='arm_2_link'>0.0895 0 -0.0015 -1.5708 0 1.5708</pose>
      <parent>arm_2_link</parent>
      <child>arm_3_link</child>
      <axis>
        <xyz>0 0 1</xyz>
        <limit>
          <lower>-3.53429</lower>
          <upper>1.5708</upper>
          <effort>26</effort>
          <velocity>2.35</velocity>
        </limit>
        <dynamics>
          <damping>40</damping>
          <friction>1</friction>
          <spring_reference>0</spring_reference>
          <spring_stiffness>0</spring_stiffness>
        </dynamics>
      </axis>
      <physics>
        <ode>
          <implicit_spring_damper>1</implicit_spring_damper>
          <cfm_damping>1</cfm_damping>
          <limit>
            <cfm>0</cfm>
            <erp>0.2</erp>
          </limit>
        </ode>
      </physics>
    </joint>
    <link name='arm_3_link'>
      <pose relative_to='arm_3_joint'>0 0 0 0 -0 0</pose>
      <inertial>
        <pose>0.007418 -0.004361 -0.134194 0 -0 0</pose>
        <mass>1.8</mass>
        <inertia>
          <ixx>0.019541</ixx>
          <ixy>-0.000105</ixy>
          <ixz>-0.001717</ixz>
          <iyy>0.019936</iyy>
          <iyz>0.000852</iyz>
          <izz>0.002864</izz>
        </inertia>
      </inertial>
      <collision name='arm_3_link_collision'>
        <pose>0 0 0 0 -0 0</pose>
        <geometry>
          <mesh>
            <scale>1 1 1</scale>
            <uri>model://tiago_description/meshes/arm/arm_3_collision.dae</uri>
          </mesh>
        </geometry>
        <surface>
          <contact>
            <ode/>
          </contact>
          <friction>
            <ode>
              <mu>0.9</mu>
              <mu2>0.9</mu2>
            </ode>
          </friction>
        </surface>
      </collision>
      <visual name='arm_3_link_visual'>
        <pose>0 0 0 0 -0 0</pose>
        <geometry>
          <mesh>
            <scale>1 1 1</scale>
            <uri>model://tiago_description/meshes/arm/arm_3.stl</uri>
          </mesh>
        </geometry>
        <material>
          <script>
            <name>Gazebo/DarkGrey</name>
            <uri>file://media/materials/scripts/gazebo.material</uri>
          </script>
        </material>
      </visual>
    </link>
    <joint name='arm_4_joint' type='revolute'>
      <pose relative_to='arm_3_link'>-0.02 -0.027 -0.222 -1.5708 -1.5708 0</pose>
      <parent>arm_3_link</parent>
      <child>arm_4_link</child>
      <axis>
        <xyz>0 0 1</xyz>
        <limit>
          <lower>-0.392699</lower>
          <upper>2.35619</upper>
          <effort>26</effort>
          <velocity>2.35</velocity>
        </limit>
        <dynamics>
          <damping>40</damping>
          <friction>1</friction>
          <spring_reference>0</spring_reference>
          <spring_stiffness>0</spring_stiffness>
        </dynamics>
      </axis>
      <physics>
        <ode>
          <implicit_spring_damper>1</implicit_spring_damper>
          <cfm_damping>1</cfm_damping>
          <limit>
            <cfm>0</cfm>
            <erp>0.2</erp>
          </limit>
        </ode>
      </physics>
    </joint>
    <link name='arm_4_link'>
      <pose relative_to='arm_4_joint'>0 0 0 0 -0 0</pose>
      <inertial>
        <pose>-0.095658 0.014666 0.018133 0 -0 0</pose>
        <mass>1.4327</mass>
        <inertia>
          <ixx>0.00204</ixx>
          <ixy>0.000725</ixy>
          <ixz>-0.00115</ixz>
          <iyy>0.008424</iyy>
          <iyz>-0.000204</iyz>
          <izz>0.008686</izz>
        </inertia>
      </inertial>
      <collision name='arm_4_link_collision'>
        <pose>0 0 0 0 -0 0</pose>
        <geometry>
          <mesh>
            <scale>1 1 1</scale>
            <uri>model://tiago_description/meshes/arm/arm_4_collision.dae</uri>
          </mesh>
        </geometry>
        <surface>
          <contact>
            <ode/>
          </contact>
          <friction>
            <ode>
              <mu>0.9</mu>
              <mu2>0.9</mu2>
            </ode>
          </friction>
        </surface>
      </collision>
      <visual name='arm_4_link_visual'>
        <pose>0 0 0 0 -0 0</pose>
        <geometry>
          <mesh>
            <scale>1 1 1</scale>
            <uri>model://tiago_description/meshes/arm/arm_4.stl</uri>
          </mesh>
        </geometry>
        <material>
          <script>
            <name>Gazebo/DarkGrey</name>
            <uri>file://media/materials/scripts/gazebo.material</uri>
          </script>
        </material>
      </visual>
    </link>
    <joint name='arm_5_joint' type='revolute'>
      <pose relative_to='arm_4_link'>-0.162 0.02 0.027 0 -1.5708 0</pose>
      <parent>arm_4_link</parent>
      <child>arm_5_link</child>
      <axis>
        <xyz>0 0 1</xyz>
        <limit>
          <lower>-2.0944</lower>
          <upper>2.0944</upper>
          <effort>3</effort>
          <velocity>1.95</velocity>
        </limit>
        <dynamics>
          <damping>1</damping>
          <friction>1</friction>
          <spring_reference>0</spring_reference>
          <spring_stiffness>0</spring_stiffness>
        </dynamics>
      </axis>
      <physics>
        <ode>
          <implicit_spring_damper>1</implicit_spring_damper>
          <cfm_damping>1</cfm_damping>
          <limit>
            <cfm>0</cfm>
            <erp>0.2</erp>
          </limit>
        </ode>
      </physics>
    </joint>
    <link name='arm_5_link'>
      <pose relative_to='arm_5_joint'>0 0 0 0 -0 0</pose>
      <inertial>
        <pose>0.001078 -0.000151 -0.077173 0 -0 0</pose>
        <mass>1.65582</mass>
        <inertia>
          <ixx>0.006138</ixx>
          <ixy>-4e-06</ixy>
          <ixz>0.000156</ixz>
          <iyy>0.00564</iyy>
          <iyz>2.2e-05</iyz>
          <izz>0.001797</izz>
        </inertia>
      </inertial>
      <collision name='arm_5_link_collision'>
        <pose>0 0 0 0 -0 0</pose>
        <geometry>
          <mesh>
            <scale>1 1 1</scale>
            <uri>model://tiago_description/meshes/arm/arm_5_collision-wrist-2010.dae</uri>
          </mesh>
        </geometry>
        <surface>
          <contact>
            <ode/>
          </contact>
          <friction>
            <ode>
              <mu>0.9</mu>
              <mu2>0.9</mu2>
            </ode>
          </friction>
        </surface>
      </collision>
      <visual name='arm_5_link_visual'>
        <pose>0 0 0 0 -0 0</pose>
        <geometry>
          <mesh>
            <scale>1 1 1</scale>
            <uri>model://tiago_description/meshes/arm/arm_5-wrist-2010.stl</uri>
          </mesh>
        </geometry>
      </visual>
    </link>
    <joint name='arm_6_joint' type='revolute'>
      <pose relative_to='arm_5_link'>0 0 0.15 -1.5708 -1.5708 0</pose>
      <parent>arm_5_link</parent>
      <child>arm_6_link</child>
      <axis>
        <xyz>0 0 1</xyz>
        <limit>
          <lower>-1.41372</lower>
          <upper>1.41372</upper>
          <effort>6.6</effort>
          <velocity>1.76</velocity>
        </limit>
        <dynamics>
          <damping>1</damping>
          <friction>1</friction>
          <spring_reference>0</spring_reference>
          <spring_stiffness>0</spring_stiffness>
        </dynamics>
      </axis>
      <physics>
        <ode>
          <implicit_spring_damper>1</implicit_spring_damper>
          <cfm_damping>1</cfm_damping>
          <limit>
            <cfm>0</cfm>
            <erp>0.2</erp>
          </limit>
        </ode>
      </physics>
    </joint>
    <link name='arm_6_link'>
      <pose relative_to='arm_6_joint'>0 0 0 0 -0 0</pose>
      <inertial>
        <pose>-0.000153 -0.003122 0.000183 0 -0 0</pose>
        <mass>0.370063</mass>
        <inertia>
          <ixx>0.000215</ixx>
          <ixy>0</ixy>
          <ixz>0</ixz>
          <iyy>0.00017</iyy>
          <iyz>2e-06</iyz>
          <izz>0.000174</izz>
        </inertia>
      </inertial>
      <collision name='arm_6_link_collision'>
        <pose>0 0 0 0 -0 0</pose>
        <geometry>
          <mesh>
            <scale>1 1 1</scale>
            <uri>model://tiago_description/meshes/arm/arm_6_collision-wrist-2010.dae</uri>
          </mesh>
        </geometry>
        <surface>
          <contact>
            <ode/>
          </contact>
          <friction>
            <ode>
              <mu>0.9</mu>
              <mu2>0.9</mu2>
            </ode>
          </friction>
        </surface>
      </collision>
      <visual name='arm_6_link_visual'>
        <pose>0 0 0 0 -0 0</pose>
        <geometry>
          <mesh>
            <scale>1 1 1</scale>
            <uri>model://tiago_description/meshes/arm/arm_6-wrist-2010.stl</uri>
          </mesh>
        </geometry>
      </visual>
    </link>
    <joint name='arm_7_joint' type='revolute'>
      <pose relative_to='arm_6_link'>0 0 0 1.5708 -0 1.5708</pose>
      <parent>arm_6_link</parent>
      <child>arm_7_link</child>
      <axis>
        <xyz>0 0 1</xyz>
        <limit>
          <lower>-2.0944</lower>
          <upper>2.0944</upper>
          <effort>6.6</effort>
          <velocity>1.76</velocity>
        </limit>
        <dynamics>
          <damping>1</damping>
          <friction>1</friction>
          <spring_reference>0</spring_reference>
          <spring_stiffness>0</spring_stiffness>
        </dynamics>
      </axis>
      <physics>
        <provide_feedback>1</provide_feedback>
        <ode>
          <implicit_spring_damper>1</implicit_spring_damper>
          <cfm_damping>1</cfm_damping>
          <limit>
            <cfm>0</cfm>
            <erp>0.2</erp>
          </limit>
          <provide_feedback>1</provide_feedback>
        </ode>
      </physics>
    </joint>
    <link name='arm_7_link'>
      <pose relative_to='arm_7_joint'>0 0 0 0 -0 0</pose>
      <inertial>
        <pose>7e-06 -2e-06 0.008314 0 -0 0</pose>
        <mass>0.334252</mass>
        <inertia>
          <ixx>0.000344653</ixx>
          <ixy>2.10247e-12</ixy>
          <ixz>3.76861e-08</ixz>
          <iyy>0.000315653</iyy>
          <iyz>-1.13058e-08</iyz>
          <izz>5.2e-05</izz>
        </inertia>
      </inertial>
      <collision name='arm_7_link_fixed_joint_lump__arm_tool_link_collision'>
        <pose>-0 0 0.047 0 -0 -1.5708</pose>
        <geometry>
          <cylinder>
            <length>0.005</length>
            <radius>0.005</radius>
          </cylinder>
        </geometry>
      </collision>
      <visual name='arm_7_link_fixed_joint_lump__arm_tool_link_visual'>
        <pose>-0 0 0.047 0 -0 -1.5708</pose>
        <geometry>
          <cylinder>
            <length>0.005</length>
            <radius>0.005</radius>
          </cylinder>
        </geometry>
      </visual>
    </link>
    <joint name='wrist_ft_joint' type='fixed'>
      <pose relative_to='arm_7_link'>-0 0 0.05385 -0 -0 -0</pose>
      <parent>arm_7_link</parent>
      <child>wrist_ft_link</child>
      <axis>
        <dynamics>
          <spring_reference>0</spring_reference>
          <spring_stiffness>0</spring_stiffness>
        </dynamics>
        <xyz>0 0 1</xyz>
        <limit>
          <lower>-1e+16</lower>
          <upper>1e+16</upper>
        </limit>
      </axis>
      <physics>
        <ode>
          <limit>
            <cfm>0</cfm>
            <erp>0.2</erp>
          </limit>
        </ode>
      </physics>
      <sensor name='wrist_ft_sensor' type='force_torque'>
        <update_rate>100</update_rate>
        <visualize>1</visualize>
        <force_torque>
          <frame>child</frame>
          <measure_direction>child_to_parent</measure_direction>
        </force_torque>
      </sensor>
    </joint>
    <link name='wrist_ft_link'>
      <pose relative_to='wrist_ft_joint'>0 0 0 0 -0 0</pose>
      <inertial>
        <pose>-0.001463 0.001403 0.053341 0 -0 0</pose>
        <mass>0.6002</mass>
        <inertia>
          <ixx>0.00159315</ixx>
          <ixy>8.19828e-06</ixy>
          <ixz>2.55845e-05</ixz>
          <iyy>0.00143715</iyy>
          <iyz>-4.54364e-06</iyz>
          <izz>0.000416414</izz>
        </inertia>
      </inertial>
      <collision name='wrist_ft_link_collision'>
        <pose>0 0 0 0 -0 0</pose>
        <geometry>
          <cylinder>
            <length>0.0157</length>
            <radius>0.0225</radius>
          </cylinder>
        </geometry>
      </collision>
      <collision name='wrist_ft_link_fixed_joint_lump__wrist_ft_tool_link_collision_1'>
        <pose>0 0 0.012725 -0 -0 -1.5708</pose>
        <geometry>
          <cylinder>
            <length>0.00975</length>
            <radius>0.025</radius>
          </cylinder>
        </geometry>
      </collision>
      <collision name='wrist_ft_link_fixed_joint_lump__hand_palm_link_collision_2'>
        <pose>0 0 0.012725 -1.5708 -1.5708 0</pose>
        <geometry>
          <mesh>
            <scale>1 1 1</scale>
            <uri>model://pal_hey5_description/meshes/palm_collision.stl</uri>
          </mesh>
        </geometry>
        <surface>
          <contact>
            <ode/>
          </contact>
          <friction>
            <ode/>
          </friction>
        </surface>
      </collision>
      <collision name='wrist_ft_link_fixed_joint_lump__hand_safety_box_collision_3'>
        <pose>0.02 0.02 0.112725 -1.5708 -1.5708 0</pose>
        <geometry>
          <box>
            <size>0.2 0.115 0.18</size>
          </box>
        </geometry>
      </collision>
      <visual name='wrist_ft_link_visual'>
        <pose>0 0 0 0 -0 0</pose>
        <geometry>
          <cylinder>
            <length>0.0157</length>
            <radius>0.0225</radius>
          </cylinder>
        </geometry>
      </visual>
      <visual name='wrist_ft_link_fixed_joint_lump__wrist_ft_tool_link_visual_1'>
        <pose>0 0 0.012725 -0 -0 -1.5708</pose>
        <geometry>
          <cylinder>
            <length>0.00975</length>
            <radius>0.025</radius>
          </cylinder>
        </geometry>
      </visual>
      <visual name='wrist_ft_link_fixed_joint_lump__hand_palm_link_visual_2'>
        <pose>0 0 0.012725 -1.5708 -1.5708 0</pose>
        <geometry>
          <mesh>
            <scale>1 1 1</scale>
            <uri>model://pal_hey5_description/meshes/palm.stl</uri>
          </mesh>
        </geometry>
        <material>
          <script>
            <name>Gazebo/Black</name>
            <uri>file://media/materials/scripts/gazebo.material</uri>
          </script>
        </material>
      </visual>
    </link>
    <joint name='hand_index_abd_joint' type='revolute'>
      <pose relative_to='wrist_ft_link'>0.0042 0.0265 0.139225 1.5708 -1.0472 1.5708</pose>
      <parent>wrist_ft_link</parent>
      <child>hand_index_abd_link</child>
      <axis>
        <xyz>0 0 1</xyz>
        <limit>
          <lower>-0.523599</lower>
          <upper>0.523599</upper>
          <effort>2</effort>
          <velocity>2</velocity>
        </limit>
        <dynamics>
          <damping>0.5</damping>
          <friction>0</friction>
          <spring_reference>0</spring_reference>
          <spring_stiffness>0</spring_stiffness>
        </dynamics>
      </axis>
    </joint>
    <link name='hand_index_abd_link'>
      <pose relative_to='hand_index_abd_joint'>0 0 0 0 -0 0</pose>
      <inertial>
        <pose>-0.0018 0 0.0028 0 -0 0</pose>
        <mass>0.018</mass>
        <inertia>
          <ixx>0.001</ixx>
          <ixy>0</ixy>
          <ixz>0</ixz>
          <iyy>0.001</iyy>
          <iyz>0</iyz>
          <izz>0.001</izz>
        </inertia>
      </inertial>
      <collision name='hand_index_abd_link_collision'>
        <pose>0 0 0 0 -0 0</pose>
        <geometry>
          <mesh>
            <scale>1 1 1</scale>
            <uri>model://pal_hey5_description/meshes/finger_abd_collision.stl</uri>
          </mesh>
        </geometry>
        <surface>
          <contact>
            <ode/>
          </contact>
          <friction>
            <ode/>
          </friction>
        </surface>
      </collision>
      <visual name='hand_index_abd_link_visual'>
        <pose>0 0 0 0 -0 0</pose>
        <geometry>
          <mesh>
            <scale>1 1 1</scale>
            <uri>model://pal_hey5_description/meshes/finger_abd_collision.stl</uri>
          </mesh>
        </geometry>
        <material>
          <script>
            <name>Gazebo/Black</name>
            <uri>file://media/materials/scripts/gazebo.material</uri>
          </script>
        </material>
      </visual>
    </link>
    <joint name='hand_index_virtual_1_joint' type='revolute'>
      <pose relative_to='hand_index_abd_link'>0.009 0 0 1.5708 -0 0</pose>
      <parent>hand_index_abd_link</parent>
      <child>hand_index_virtual_1_link</child>
      <axis>
        <xyz>0 0 1</xyz>
        <limit>
          <lower>0</lower>
          <upper>0.785398</upper>
          <effort>2</effort>
          <velocity>2</velocity>
        </limit>
        <dynamics>
          <damping>0.5</damping>
          <friction>0</friction>
          <spring_reference>0</spring_reference>
          <spring_stiffness>0</spring_stiffness>
        </dynamics>
      </axis>
    </joint>
    <link name='hand_index_virtual_1_link'>
      <pose relative_to='hand_index_virtual_1_joint'>0 0 0 0 -0 0</pose>
      <inertial>
        <pose>0.0065 0 0 0 -0 0</pose>
        <mass>0.01</mass>
        <inertia>
          <ixx>0.001</ixx>
          <ixy>0</ixy>
          <ixz>0</ixz>
          <iyy>0.001</iyy>
          <iyz>0</iyz>
          <izz>0.001</izz>
        </inertia>
      </inertial>
      <collision name='hand_index_virtual_1_link_collision'>
        <pose>0 0 0 0 -0 0</pose>
        <geometry>
          <box>
            <size>0.013 0.002 0.012</size>
          </box>
        </geometry>
        <surface>
          <contact>
            <ode/>
          </contact>
          <friction>
            <ode/>
          </friction>
        </surface>
      </collision>
      <visual name='hand_index_virtual_1_link_visual'>
        <pose>0.0065 0 0 0 -0 0</pose>
        <geometry>
          <box>
            <size>0.013 0.002 0.012</size>
          </box>
        </geometry>
        <material>
          <script>
            <name>Gazebo/Black</name>
            <uri>file://media/materials/scripts/gazebo.material</uri>
          </script>
        </material>
      </visual>
    </link>
    <joint name='hand_index_flex_1_joint' type='revolute'>
      <pose relative_to='hand_index_virtual_1_link'>0.013 0 0 0 -0 0</pose>
      <parent>hand_index_virtual_1_link</parent>
      <child>hand_index_flex_1_link</child>
      <axis>
        <xyz>0 0 1</xyz>
        <limit>
          <lower>0</lower>
          <upper>0.785398</upper>
          <effort>2</effort>
          <velocity>2</velocity>
        </limit>
        <dynamics>
          <damping>0.5</damping>
          <friction>0</friction>
          <spring_reference>0</spring_reference>
          <spring_stiffness>0</spring_stiffness>
        </dynamics>
      </axis>
    </joint>
    <link name='hand_index_flex_1_link'>
      <pose relative_to='hand_index_flex_1_joint'>0 0 0 0 -0 0</pose>
      <inertial>
        <pose>0.0047 0.0031 0 0 -0 0</pose>
        <mass>0.009</mass>
        <inertia>
          <ixx>0.001</ixx>
          <ixy>0</ixy>
          <ixz>0</ixz>
          <iyy>0.001</iyy>
          <iyz>0</iyz>
          <izz>0.001</izz>
        </inertia>
      </inertial>
      <collision name='hand_index_flex_1_link_collision'>
        <pose>0 0 0 0 -0 0</pose>
        <geometry>
          <mesh>
            <scale>1 1 1</scale>
            <uri>model://pal_hey5_description/meshes/finger_flex_collision.stl</uri>
          </mesh>
        </geometry>
        <surface>
          <contact>
            <ode/>
          </contact>
          <friction>
            <ode/>
          </friction>
        </surface>
      </collision>
      <visual name='hand_index_flex_1_link_visual'>
        <pose>0 0 0 0 -0 0</pose>
        <geometry>
          <mesh>
            <scale>1 1 1</scale>
            <uri>model://pal_hey5_description/meshes/finger_flex_collision.stl</uri>
          </mesh>
        </geometry>
        <material>
          <script>
            <name>Gazebo/Black</name>
            <uri>file://media/materials/scripts/gazebo.material</uri>
          </script>
        </material>
      </visual>
    </link>
    <joint name='hand_index_virtual_2_joint' type='revolute'>
      <pose relative_to='hand_index_flex_1_link'>0.009 0 0 0 -0 0</pose>
      <parent>hand_index_flex_1_link</parent>
      <child>hand_index_virtual_2_link</child>
      <axis>
        <xyz>0 0 1</xyz>
        <limit>
          <lower>0</lower>
          <upper>0.785398</upper>
          <effort>2</effort>
          <velocity>2</velocity>
        </limit>
        <dynamics>
          <damping>0.5</damping>
          <friction>0</friction>
          <spring_reference>0</spring_reference>
          <spring_stiffness>0</spring_stiffness>
        </dynamics>
      </axis>
    </joint>
    <link name='hand_index_virtual_2_link'>
      <pose relative_to='hand_index_virtual_2_joint'>0 0 0 0 -0 0</pose>
      <inertial>
        <pose>0.0065 0 0 0 -0 0</pose>
        <mass>0.01</mass>
        <inertia>
          <ixx>0.001</ixx>
          <ixy>0</ixy>
          <ixz>0</ixz>
          <iyy>0.001</iyy>
          <iyz>0</iyz>
          <izz>0.001</izz>
        </inertia>
      </inertial>
      <collision name='hand_index_virtual_2_link_collision'>
        <pose>0 0 0 0 -0 0</pose>
        <geometry>
          <box>
            <size>0.013 0.002 0.012</size>
          </box>
        </geometry>
        <surface>
          <contact>
            <ode/>
          </contact>
          <friction>
            <ode/>
          </friction>
        </surface>
      </collision>
      <visual name='hand_index_virtual_2_link_visual'>
        <pose>0.0065 0 0 0 -0 0</pose>
        <geometry>
          <box>
            <size>0.013 0.002 0.012</size>
          </box>
        </geometry>
        <material>
          <script>
            <name>Gazebo/Black</name>
            <uri>file://media/materials/scripts/gazebo.material</uri>
          </script>
        </material>
      </visual>
    </link>
    <joint name='hand_index_flex_2_joint' type='revolute'>
      <pose relative_to='hand_index_virtual_2_link'>0.013 0 0 0 -0 0</pose>
      <parent>hand_index_virtual_2_link</parent>
      <child>hand_index_flex_2_link</child>
      <axis>
        <xyz>0 0 1</xyz>
        <limit>
          <lower>0</lower>
          <upper>0.785398</upper>
          <effort>2</effort>
          <velocity>2</velocity>
        </limit>
        <dynamics>
          <damping>0.5</damping>
          <friction>0</friction>
          <spring_reference>0</spring_reference>
          <spring_stiffness>0</spring_stiffness>
        </dynamics>
      </axis>
    </joint>
    <link name='hand_index_flex_2_link'>
      <pose relative_to='hand_index_flex_2_joint'>0 0 0 0 -0 0</pose>
      <inertial>
        <pose>0.0047 0.0031 0 0 -0 0</pose>
        <mass>0.009</mass>
        <inertia>
          <ixx>0.001</ixx>
          <ixy>0</ixy>
          <ixz>0</ixz>
          <iyy>0.001</iyy>
          <iyz>0</iyz>
          <izz>0.001</izz>
        </inertia>
      </inertial>
      <collision name='hand_index_flex_2_link_collision'>
        <pose>0 0 0 0 -0 0</pose>
        <geometry>
          <mesh>
            <scale>1 1 1</scale>
            <uri>model://pal_hey5_description/meshes/finger_flex_collision.stl</uri>
          </mesh>
        </geometry>
        <surface>
          <contact>
            <ode/>
          </contact>
          <friction>
            <ode/>
          </friction>
        </surface>
      </collision>
      <visual name='hand_index_flex_2_link_visual'>
        <pose>0 0 0 0 -0 0</pose>
        <geometry>
          <mesh>
            <scale>1 1 1</scale>
            <uri>model://pal_hey5_description/meshes/finger_flex_collision.stl</uri>
          </mesh>
        </geometry>
        <material>
          <script>
            <name>Gazebo/Black</name>
            <uri>file://media/materials/scripts/gazebo.material</uri>
          </script>
        </material>
      </visual>
    </link>
    <joint name='hand_index_virtual_3_joint' type='revolute'>
      <pose relative_to='hand_index_flex_2_link'>0.009 0 0 0 -0 0</pose>
      <parent>hand_index_flex_2_link</parent>
      <child>hand_index_virtual_3_link</child>
      <axis>
        <xyz>0 0 1</xyz>
        <limit>
          <lower>0</lower>
          <upper>0.785398</upper>
          <effort>2</effort>
          <velocity>2</velocity>
        </limit>
        <dynamics>
          <damping>0.5</damping>
          <friction>0</friction>
          <spring_reference>0</spring_reference>
          <spring_stiffness>0</spring_stiffness>
        </dynamics>
      </axis>
    </joint>
    <link name='hand_index_virtual_3_link'>
      <pose relative_to='hand_index_virtual_3_joint'>0 0 0 0 -0 0</pose>
      <inertial>
        <pose>0.0065 0 0 0 -0 0</pose>
        <mass>0.01</mass>
        <inertia>
          <ixx>0.001</ixx>
          <ixy>0</ixy>
          <ixz>0</ixz>
          <iyy>0.001</iyy>
          <iyz>0</iyz>
          <izz>0.001</izz>
        </inertia>
      </inertial>
      <collision name='hand_index_virtual_3_link_collision'>
        <pose>0 0 0 0 -0 0</pose>
        <geometry>
          <box>
            <size>0.013 0.002 0.012</size>
          </box>
        </geometry>
        <surface>
          <contact>
            <ode/>
          </contact>
          <friction>
            <ode/>
          </friction>
        </surface>
      </collision>
      <visual name='hand_index_virtual_3_link_visual'>
        <pose>0.0065 0 0 0 -0 0</pose>
        <geometry>
          <box>
            <size>0.013 0.002 0.012</size>
          </box>
        </geometry>
        <material>
          <script>
            <name>Gazebo/Black</name>
            <uri>file://media/materials/scripts/gazebo.material</uri>
          </script>
        </material>
      </visual>
    </link>
    <joint name='hand_index_flex_3_joint' type='revolute'>
      <pose relative_to='hand_index_virtual_3_link'>0.013 0 0 0 -0 0</pose>
      <parent>hand_index_virtual_3_link</parent>
      <child>hand_index_flex_3_link</child>
      <axis>
        <xyz>0 0 1</xyz>
        <limit>
          <lower>0</lower>
          <upper>0.785398</upper>
          <effort>2</effort>
          <velocity>2</velocity>
        </limit>
        <dynamics>
          <damping>0.5</damping>
          <friction>0</friction>
          <spring_reference>0</spring_reference>
          <spring_stiffness>0</spring_stiffness>
        </dynamics>
      </axis>
    </joint>
    <link name='hand_index_flex_3_link'>
      <pose relative_to='hand_index_flex_3_joint'>0 0 0 0 -0 0</pose>
      <inertial>
        <pose>0.0096 0.003 0 0 -0 0</pose>
        <mass>0.015</mass>
        <inertia>
          <ixx>0.001</ixx>
          <ixy>0</ixy>
          <ixz>0</ixz>
          <iyy>0.001</iyy>
          <iyz>0</iyz>
          <izz>0.001</izz>
        </inertia>
      </inertial>
      <collision name='hand_index_flex_3_link_collision'>
        <pose>0 0 0 0 -0 0</pose>
        <geometry>
          <mesh>
            <scale>1 1 1</scale>
            <uri>model://pal_hey5_description/meshes/finger_flex_tip_collision.stl</uri>
          </mesh>
        </geometry>
        <surface>
          <contact>
            <ode/>
          </contact>
          <friction>
            <ode/>
          </friction>
        </surface>
      </collision>
      <visual name='hand_index_flex_3_link_visual'>
        <pose>0 0 0 0 -0 0</pose>
        <geometry>
          <mesh>
            <scale>1 1 1</scale>
            <uri>model://pal_hey5_description/meshes/finger_flex_tip_collision.stl</uri>
          </mesh>
        </geometry>
        <material>
          <script>
            <name>Gazebo/Black</name>
            <uri>file://media/materials/scripts/gazebo.material</uri>
          </script>
        </material>
      </visual>
    </link>
    <joint name='hand_index_joint' type='revolute'>
      <pose relative_to='wrist_ft_link'>0 0 0.012725 -1.5708 -1.5708 0</pose>
      <parent>wrist_ft_link</parent>
      <child>hand_index_link</child>
      <axis>
        <xyz>0 0 1</xyz>
        <limit>
          <lower>-3.05433</lower>
          <upper>6.80678</upper>
          <effort>2</effort>
          <velocity>3.35</velocity>
        </limit>
        <dynamics>
          <damping>0.5</damping>
          <friction>0</friction>
          <spring_reference>0</spring_reference>
          <spring_stiffness>0</spring_stiffness>
        </dynamics>
      </axis>
    </joint>
    <link name='hand_index_link'>
      <pose relative_to='hand_index_joint'>0 0 0 0 -0 0</pose>
      <inertial>
        <pose>0 0 0 0 -0 0</pose>
        <mass>0.05</mass>
        <inertia>
          <ixx>0.001</ixx>
          <ixy>0</ixy>
          <ixz>0</ixz>
          <iyy>0.001</iyy>
          <iyz>0</iyz>
          <izz>0.001</izz>
        </inertia>
      </inertial>
      <collision name='hand_index_link_collision'>
        <pose>0 0 0 0 -0 0</pose>
        <geometry>
          <sphere>
            <radius>0.001</radius>
          </sphere>
        </geometry>
      </collision>
      <visual name='hand_index_link_visual'>
        <pose>0 0 0 0 -0 0</pose>
        <geometry>
          <sphere>
            <radius>0.001</radius>
          </sphere>
        </geometry>
      </visual>
    </link>
    <joint name='hand_little_abd_joint' type='revolute'>
      <pose relative_to='wrist_ft_link'>0.0042 -0.032 0.129225 -1.5708 -1.0472 -1.5708</pose>
      <parent>wrist_ft_link</parent>
      <child>hand_little_abd_link</child>
      <axis>
        <xyz>0 0 1</xyz>
        <limit>
          <lower>-0.523599</lower>
          <upper>0.523599</upper>
          <effort>2</effort>
          <velocity>2</velocity>
        </limit>
        <dynamics>
          <damping>0.5</damping>
          <friction>0</friction>
          <spring_reference>0</spring_reference>
          <spring_stiffness>0</spring_stiffness>
        </dynamics>
      </axis>
    </joint>
    <link name='hand_little_abd_link'>
      <pose relative_to='hand_little_abd_joint'>0 0 0 0 -0 0</pose>
      <inertial>
        <pose>-0.0018 0 0.0028 0 -0 0</pose>
        <mass>0.018</mass>
        <inertia>
          <ixx>0.001</ixx>
          <ixy>0</ixy>
          <ixz>0</ixz>
          <iyy>0.001</iyy>
          <iyz>0</iyz>
          <izz>0.001</izz>
        </inertia>
      </inertial>
      <collision name='hand_little_abd_link_collision'>
        <pose>0 0 0 0 -0 0</pose>
        <geometry>
          <mesh>
            <scale>1 1 1</scale>
            <uri>model://pal_hey5_description/meshes/finger_abd_collision.stl</uri>
          </mesh>
        </geometry>
        <surface>
          <contact>
            <ode/>
          </contact>
          <friction>
            <ode/>
          </friction>
        </surface>
      </collision>
      <visual name='hand_little_abd_link_visual'>
        <pose>0 0 0 0 -0 0</pose>
        <geometry>
          <mesh>
            <scale>1 1 1</scale>
            <uri>model://pal_hey5_description/meshes/finger_abd_collision.stl</uri>
          </mesh>
        </geometry>
        <material>
          <script>
            <name>Gazebo/Black</name>
            <uri>file://media/materials/scripts/gazebo.material</uri>
          </script>
        </material>
      </visual>
    </link>
    <joint name='hand_little_virtual_1_joint' type='revolute'>
      <pose relative_to='hand_little_abd_link'>0.009 0 0 1.5708 -0 0</pose>
      <parent>hand_little_abd_link</parent>
      <child>hand_little_virtual_1_link</child>
      <axis>
        <xyz>0 0 1</xyz>
        <limit>
          <lower>0</lower>
          <upper>0.785398</upper>
          <effort>2</effort>
          <velocity>2</velocity>
        </limit>
        <dynamics>
          <damping>0.5</damping>
          <friction>0</friction>
          <spring_reference>0</spring_reference>
          <spring_stiffness>0</spring_stiffness>
        </dynamics>
      </axis>
    </joint>
    <link name='hand_little_virtual_1_link'>
      <pose relative_to='hand_little_virtual_1_joint'>0 0 0 0 -0 0</pose>
      <inertial>
        <pose>0.0065 0 0 0 -0 0</pose>
        <mass>0.01</mass>
        <inertia>
          <ixx>0.001</ixx>
          <ixy>0</ixy>
          <ixz>0</ixz>
          <iyy>0.001</iyy>
          <iyz>0</iyz>
          <izz>0.001</izz>
        </inertia>
      </inertial>
      <collision name='hand_little_virtual_1_link_collision'>
        <pose>0 0 0 0 -0 0</pose>
        <geometry>
          <box>
            <size>0.013 0.002 0.012</size>
          </box>
        </geometry>
        <surface>
          <contact>
            <ode/>
          </contact>
          <friction>
            <ode/>
          </friction>
        </surface>
      </collision>
      <visual name='hand_little_virtual_1_link_visual'>
        <pose>0.0065 0 0 0 -0 0</pose>
        <geometry>
          <box>
            <size>0.013 0.002 0.012</size>
          </box>
        </geometry>
        <material>
          <script>
            <name>Gazebo/Black</name>
            <uri>file://media/materials/scripts/gazebo.material</uri>
          </script>
        </material>
      </visual>
    </link>
    <joint name='hand_little_flex_1_joint' type='revolute'>
      <pose relative_to='hand_little_virtual_1_link'>0.013 0 0 0 -0 0</pose>
      <parent>hand_little_virtual_1_link</parent>
      <child>hand_little_flex_1_link</child>
      <axis>
        <xyz>0 0 1</xyz>
        <limit>
          <lower>0</lower>
          <upper>0.785398</upper>
          <effort>2</effort>
          <velocity>2</velocity>
        </limit>
        <dynamics>
          <damping>0.5</damping>
          <friction>0</friction>
          <spring_reference>0</spring_reference>
          <spring_stiffness>0</spring_stiffness>
        </dynamics>
      </axis>
    </joint>
    <link name='hand_little_flex_1_link'>
      <pose relative_to='hand_little_flex_1_joint'>0 0 0 0 -0 0</pose>
      <inertial>
        <pose>0.0047 0.0031 0 0 -0 0</pose>
        <mass>0.009</mass>
        <inertia>
          <ixx>0.001</ixx>
          <ixy>0</ixy>
          <ixz>0</ixz>
          <iyy>0.001</iyy>
          <iyz>0</iyz>
          <izz>0.001</izz>
        </inertia>
      </inertial>
      <collision name='hand_little_flex_1_link_collision'>
        <pose>0 0 0 0 -0 0</pose>
        <geometry>
          <mesh>
            <scale>1 1 1</scale>
            <uri>model://pal_hey5_description/meshes/finger_flex_collision.stl</uri>
          </mesh>
        </geometry>
        <surface>
          <contact>
            <ode/>
          </contact>
          <friction>
            <ode/>
          </friction>
        </surface>
      </collision>
      <visual name='hand_little_flex_1_link_visual'>
        <pose>0 0 0 0 -0 0</pose>
        <geometry>
          <mesh>
            <scale>1 1 1</scale>
            <uri>model://pal_hey5_description/meshes/finger_flex_collision.stl</uri>
          </mesh>
        </geometry>
        <material>
          <script>
            <name>Gazebo/Black</name>
            <uri>file://media/materials/scripts/gazebo.material</uri>
          </script>
        </material>
      </visual>
    </link>
    <joint name='hand_little_virtual_2_joint' type='revolute'>
      <pose relative_to='hand_little_flex_1_link'>0.009 0 0 0 -0 0</pose>
      <parent>hand_little_flex_1_link</parent>
      <child>hand_little_virtual_2_link</child>
      <axis>
        <xyz>0 0 1</xyz>
        <limit>
          <lower>0</lower>
          <upper>0.785398</upper>
          <effort>2</effort>
          <velocity>2</velocity>
        </limit>
        <dynamics>
          <damping>0.5</damping>
          <friction>0</friction>
          <spring_reference>0</spring_reference>
          <spring_stiffness>0</spring_stiffness>
        </dynamics>
      </axis>
    </joint>
    <link name='hand_little_virtual_2_link'>
      <pose relative_to='hand_little_virtual_2_joint'>0 0 0 0 -0 0</pose>
      <inertial>
        <pose>0.0065 0 0 0 -0 0</pose>
        <mass>0.01</mass>
        <inertia>
          <ixx>0.001</ixx>
          <ixy>0</ixy>
          <ixz>0</ixz>
          <iyy>0.001</iyy>
          <iyz>0</iyz>
          <izz>0.001</izz>
        </inertia>
      </inertial>
      <collision name='hand_little_virtual_2_link_collision'>
        <pose>0 0 0 0 -0 0</pose>
        <geometry>
          <box>
            <size>0.013 0.002 0.012</size>
          </box>
        </geometry>
        <surface>
          <contact>
            <ode/>
          </contact>
          <friction>
            <ode/>
          </friction>
        </surface>
      </collision>
      <visual name='hand_little_virtual_2_link_visual'>
        <pose>0.0065 0 0 0 -0 0</pose>
        <geometry>
          <box>
            <size>0.013 0.002 0.012</size>
          </box>
        </geometry>
        <material>
          <script>
            <name>Gazebo/Black</name>
            <uri>file://media/materials/scripts/gazebo.material</uri>
          </script>
        </material>
      </visual>
    </link>
    <joint name='hand_little_flex_2_joint' type='revolute'>
      <pose relative_to='hand_little_virtual_2_link'>0.013 0 0 0 -0 0</pose>
      <parent>hand_little_virtual_2_link</parent>
      <child>hand_little_flex_2_link</child>
      <axis>
        <xyz>0 0 1</xyz>
        <limit>
          <lower>0</lower>
          <upper>0.785398</upper>
          <effort>2</effort>
          <velocity>2</velocity>
        </limit>
        <dynamics>
          <damping>0.5</damping>
          <friction>0</friction>
          <spring_reference>0</spring_reference>
          <spring_stiffness>0</spring_stiffness>
        </dynamics>
      </axis>
    </joint>
    <link name='hand_little_flex_2_link'>
      <pose relative_to='hand_little_flex_2_joint'>0 0 0 0 -0 0</pose>
      <inertial>
        <pose>0.0047 0.0031 0 0 -0 0</pose>
        <mass>0.009</mass>
        <inertia>
          <ixx>0.001</ixx>
          <ixy>0</ixy>
          <ixz>0</ixz>
          <iyy>0.001</iyy>
          <iyz>0</iyz>
          <izz>0.001</izz>
        </inertia>
      </inertial>
      <collision name='hand_little_flex_2_link_collision'>
        <pose>0 0 0 0 -0 0</pose>
        <geometry>
          <mesh>
            <scale>1 1 1</scale>
            <uri>model://pal_hey5_description/meshes/finger_flex_collision.stl</uri>
          </mesh>
        </geometry>
        <surface>
          <contact>
            <ode/>
          </contact>
          <friction>
            <ode/>
          </friction>
        </surface>
      </collision>
      <visual name='hand_little_flex_2_link_visual'>
        <pose>0 0 0 0 -0 0</pose>
        <geometry>
          <mesh>
            <scale>1 1 1</scale>
            <uri>model://pal_hey5_description/meshes/finger_flex_collision.stl</uri>
          </mesh>
        </geometry>
        <material>
          <script>
            <name>Gazebo/Black</name>
            <uri>file://media/materials/scripts/gazebo.material</uri>
          </script>
        </material>
      </visual>
    </link>
    <joint name='hand_little_virtual_3_joint' type='revolute'>
      <pose relative_to='hand_little_flex_2_link'>0.009 0 0 0 -0 0</pose>
      <parent>hand_little_flex_2_link</parent>
      <child>hand_little_virtual_3_link</child>
      <axis>
        <xyz>0 0 1</xyz>
        <limit>
          <lower>0</lower>
          <upper>0.785398</upper>
          <effort>2</effort>
          <velocity>2</velocity>
        </limit>
        <dynamics>
          <damping>0.5</damping>
          <friction>0</friction>
          <spring_reference>0</spring_reference>
          <spring_stiffness>0</spring_stiffness>
        </dynamics>
      </axis>
    </joint>
    <link name='hand_little_virtual_3_link'>
      <pose relative_to='hand_little_virtual_3_joint'>0 0 0 0 -0 0</pose>
      <inertial>
        <pose>0.0065 0 0 0 -0 0</pose>
        <mass>0.01</mass>
        <inertia>
          <ixx>0.001</ixx>
          <ixy>0</ixy>
          <ixz>0</ixz>
          <iyy>0.001</iyy>
          <iyz>0</iyz>
          <izz>0.001</izz>
        </inertia>
      </inertial>
      <collision name='hand_little_virtual_3_link_collision'>
        <pose>0 0 0 0 -0 0</pose>
        <geometry>
          <box>
            <size>0.013 0.002 0.012</size>
          </box>
        </geometry>
        <surface>
          <contact>
            <ode/>
          </contact>
          <friction>
            <ode/>
          </friction>
        </surface>
      </collision>
      <visual name='hand_little_virtual_3_link_visual'>
        <pose>0.0065 0 0 0 -0 0</pose>
        <geometry>
          <box>
            <size>0.013 0.002 0.012</size>
          </box>
        </geometry>
        <material>
          <script>
            <name>Gazebo/Black</name>
            <uri>file://media/materials/scripts/gazebo.material</uri>
          </script>
        </material>
      </visual>
    </link>
    <joint name='hand_little_flex_3_joint' type='revolute'>
      <pose relative_to='hand_little_virtual_3_link'>0.013 0 0 0 -0 0</pose>
      <parent>hand_little_virtual_3_link</parent>
      <child>hand_little_flex_3_link</child>
      <axis>
        <xyz>0 0 1</xyz>
        <limit>
          <lower>0</lower>
          <upper>0.785398</upper>
          <effort>2</effort>
          <velocity>2</velocity>
        </limit>
        <dynamics>
          <damping>0.5</damping>
          <friction>0</friction>
          <spring_reference>0</spring_reference>
          <spring_stiffness>0</spring_stiffness>
        </dynamics>
      </axis>
    </joint>
    <link name='hand_little_flex_3_link'>
      <pose relative_to='hand_little_flex_3_joint'>0 0 0 0 -0 0</pose>
      <inertial>
        <pose>0.0096 0.003 0 0 -0 0</pose>
        <mass>0.015</mass>
        <inertia>
          <ixx>0.001</ixx>
          <ixy>0</ixy>
          <ixz>0</ixz>
          <iyy>0.001</iyy>
          <iyz>0</iyz>
          <izz>0.001</izz>
        </inertia>
      </inertial>
      <collision name='hand_little_flex_3_link_collision'>
        <pose>0 0 0 0 -0 0</pose>
        <geometry>
          <mesh>
            <scale>1 1 1</scale>
            <uri>model://pal_hey5_description/meshes/finger_flex_tip_collision.stl</uri>
          </mesh>
        </geometry>
        <surface>
          <contact>
            <ode/>
          </contact>
          <friction>
            <ode/>
          </friction>
        </surface>
      </collision>
      <visual name='hand_little_flex_3_link_visual'>
        <pose>0 0 0 0 -0 0</pose>
        <geometry>
          <mesh>
            <scale>1 1 1</scale>
            <uri>model://pal_hey5_description/meshes/finger_flex_tip_collision.stl</uri>
          </mesh>
        </geometry>
        <material>
          <script>
            <name>Gazebo/Black</name>
            <uri>file://media/materials/scripts/gazebo.material</uri>
          </script>
        </material>
      </visual>
    </link>
    <joint name='hand_middle_abd_joint' type='revolute'>
      <pose relative_to='wrist_ft_link'>0.0042 0.007 0.146225 -3.14159 -1.5708 0</pose>
      <parent>wrist_ft_link</parent>
      <child>hand_middle_abd_link</child>
      <axis>
        <xyz>0 0 1</xyz>
        <limit>
          <lower>-0.523599</lower>
          <upper>0.523599</upper>
          <effort>2</effort>
          <velocity>2</velocity>
        </limit>
        <dynamics>
          <damping>0.5</damping>
          <friction>0</friction>
          <spring_reference>0</spring_reference>
          <spring_stiffness>0</spring_stiffness>
        </dynamics>
      </axis>
    </joint>
    <link name='hand_middle_abd_link'>
      <pose relative_to='hand_middle_abd_joint'>0 0 0 0 -0 0</pose>
      <inertial>
        <pose>-0.0018 0 0.0028 0 -0 0</pose>
        <mass>0.018</mass>
        <inertia>
          <ixx>0.001</ixx>
          <ixy>0</ixy>
          <ixz>0</ixz>
          <iyy>0.001</iyy>
          <iyz>0</iyz>
          <izz>0.001</izz>
        </inertia>
      </inertial>
      <collision name='hand_middle_abd_link_collision'>
        <pose>0 0 0 0 -0 0</pose>
        <geometry>
          <mesh>
            <scale>1 1 1</scale>
            <uri>model://pal_hey5_description/meshes/finger_abd_collision.stl</uri>
          </mesh>
        </geometry>
        <surface>
          <contact>
            <ode/>
          </contact>
          <friction>
            <ode/>
          </friction>
        </surface>
      </collision>
      <visual name='hand_middle_abd_link_visual'>
        <pose>0 0 0 0 -0 0</pose>
        <geometry>
          <mesh>
            <scale>1 1 1</scale>
            <uri>model://pal_hey5_description/meshes/finger_abd_collision.stl</uri>
          </mesh>
        </geometry>
        <material>
          <script>
            <name>Gazebo/Black</name>
            <uri>file://media/materials/scripts/gazebo.material</uri>
          </script>
        </material>
      </visual>
    </link>
    <joint name='hand_middle_virtual_1_joint' type='revolute'>
      <pose relative_to='hand_middle_abd_link'>0.009 0 0 1.5708 -0 0</pose>
      <parent>hand_middle_abd_link</parent>
      <child>hand_middle_virtual_1_link</child>
      <axis>
        <xyz>0 0 1</xyz>
        <limit>
          <lower>0</lower>
          <upper>0.785398</upper>
          <effort>2</effort>
          <velocity>2</velocity>
        </limit>
        <dynamics>
          <damping>0.5</damping>
          <friction>0</friction>
          <spring_reference>0</spring_reference>
          <spring_stiffness>0</spring_stiffness>
        </dynamics>
      </axis>
    </joint>
    <link name='hand_middle_virtual_1_link'>
      <pose relative_to='hand_middle_virtual_1_joint'>0 0 0 0 -0 0</pose>
      <inertial>
        <pose>0.0065 0 0 0 -0 0</pose>
        <mass>0.01</mass>
        <inertia>
          <ixx>0.001</ixx>
          <ixy>0</ixy>
          <ixz>0</ixz>
          <iyy>0.001</iyy>
          <iyz>0</iyz>
          <izz>0.001</izz>
        </inertia>
      </inertial>
      <collision name='hand_middle_virtual_1_link_collision'>
        <pose>0 0 0 0 -0 0</pose>
        <geometry>
          <box>
            <size>0.013 0.002 0.012</size>
          </box>
        </geometry>
        <surface>
          <contact>
            <ode/>
          </contact>
          <friction>
            <ode/>
          </friction>
        </surface>
      </collision>
      <visual name='hand_middle_virtual_1_link_visual'>
        <pose>0.0065 0 0 0 -0 0</pose>
        <geometry>
          <box>
            <size>0.013 0.002 0.012</size>
          </box>
        </geometry>
        <material>
          <script>
            <name>Gazebo/Black</name>
            <uri>file://media/materials/scripts/gazebo.material</uri>
          </script>
        </material>
      </visual>
    </link>
    <joint name='hand_middle_flex_1_joint' type='revolute'>
      <pose relative_to='hand_middle_virtual_1_link'>0.013 0 0 0 -0 0</pose>
      <parent>hand_middle_virtual_1_link</parent>
      <child>hand_middle_flex_1_link</child>
      <axis>
        <xyz>0 0 1</xyz>
        <limit>
          <lower>0</lower>
          <upper>0.785398</upper>
          <effort>2</effort>
          <velocity>2</velocity>
        </limit>
        <dynamics>
          <damping>0.5</damping>
          <friction>0</friction>
          <spring_reference>0</spring_reference>
          <spring_stiffness>0</spring_stiffness>
        </dynamics>
      </axis>
    </joint>
    <link name='hand_middle_flex_1_link'>
      <pose relative_to='hand_middle_flex_1_joint'>0 0 0 0 -0 0</pose>
      <inertial>
        <pose>0.0047 0.0031 0 0 -0 0</pose>
        <mass>0.009</mass>
        <inertia>
          <ixx>0.001</ixx>
          <ixy>0</ixy>
          <ixz>0</ixz>
          <iyy>0.001</iyy>
          <iyz>0</iyz>
          <izz>0.001</izz>
        </inertia>
      </inertial>
      <collision name='hand_middle_flex_1_link_collision'>
        <pose>0 0 0 0 -0 0</pose>
        <geometry>
          <mesh>
            <scale>1 1 1</scale>
            <uri>model://pal_hey5_description/meshes/finger_flex_collision.stl</uri>
          </mesh>
        </geometry>
        <surface>
          <contact>
            <ode/>
          </contact>
          <friction>
            <ode/>
          </friction>
        </surface>
      </collision>
      <visual name='hand_middle_flex_1_link_visual'>
        <pose>0 0 0 0 -0 0</pose>
        <geometry>
          <mesh>
            <scale>1 1 1</scale>
            <uri>model://pal_hey5_description/meshes/finger_flex_collision.stl</uri>
          </mesh>
        </geometry>
        <material>
          <script>
            <name>Gazebo/Black</name>
            <uri>file://media/materials/scripts/gazebo.material</uri>
          </script>
        </material>
      </visual>
    </link>
    <joint name='hand_middle_virtual_2_joint' type='revolute'>
      <pose relative_to='hand_middle_flex_1_link'>0.009 0 0 0 -0 0</pose>
      <parent>hand_middle_flex_1_link</parent>
      <child>hand_middle_virtual_2_link</child>
      <axis>
        <xyz>0 0 1</xyz>
        <limit>
          <lower>0</lower>
          <upper>0.785398</upper>
          <effort>2</effort>
          <velocity>2</velocity>
        </limit>
        <dynamics>
          <damping>0.5</damping>
          <friction>0</friction>
          <spring_reference>0</spring_reference>
          <spring_stiffness>0</spring_stiffness>
        </dynamics>
      </axis>
    </joint>
    <link name='hand_middle_virtual_2_link'>
      <pose relative_to='hand_middle_virtual_2_joint'>0 0 0 0 -0 0</pose>
      <inertial>
        <pose>0.0065 0 0 0 -0 0</pose>
        <mass>0.01</mass>
        <inertia>
          <ixx>0.001</ixx>
          <ixy>0</ixy>
          <ixz>0</ixz>
          <iyy>0.001</iyy>
          <iyz>0</iyz>
          <izz>0.001</izz>
        </inertia>
      </inertial>
      <collision name='hand_middle_virtual_2_link_collision'>
        <pose>0 0 0 0 -0 0</pose>
        <geometry>
          <box>
            <size>0.013 0.002 0.012</size>
          </box>
        </geometry>
        <surface>
          <contact>
            <ode/>
          </contact>
          <friction>
            <ode/>
          </friction>
        </surface>
      </collision>
      <visual name='hand_middle_virtual_2_link_visual'>
        <pose>0.0065 0 0 0 -0 0</pose>
        <geometry>
          <box>
            <size>0.013 0.002 0.012</size>
          </box>
        </geometry>
        <material>
          <script>
            <name>Gazebo/Black</name>
            <uri>file://media/materials/scripts/gazebo.material</uri>
          </script>
        </material>
      </visual>
    </link>
    <joint name='hand_middle_flex_2_joint' type='revolute'>
      <pose relative_to='hand_middle_virtual_2_link'>0.013 0 0 0 -0 0</pose>
      <parent>hand_middle_virtual_2_link</parent>
      <child>hand_middle_flex_2_link</child>
      <axis>
        <xyz>0 0 1</xyz>
        <limit>
          <lower>0</lower>
          <upper>0.785398</upper>
          <effort>2</effort>
          <velocity>2</velocity>
        </limit>
        <dynamics>
          <damping>0.5</damping>
          <friction>0</friction>
          <spring_reference>0</spring_reference>
          <spring_stiffness>0</spring_stiffness>
        </dynamics>
      </axis>
    </joint>
    <link name='hand_middle_flex_2_link'>
      <pose relative_to='hand_middle_flex_2_joint'>0 0 0 0 -0 0</pose>
      <inertial>
        <pose>0.0047 0.0031 0 0 -0 0</pose>
        <mass>0.009</mass>
        <inertia>
          <ixx>0.001</ixx>
          <ixy>0</ixy>
          <ixz>0</ixz>
          <iyy>0.001</iyy>
          <iyz>0</iyz>
          <izz>0.001</izz>
        </inertia>
      </inertial>
      <collision name='hand_middle_flex_2_link_collision'>
        <pose>0 0 0 0 -0 0</pose>
        <geometry>
          <mesh>
            <scale>1 1 1</scale>
            <uri>model://pal_hey5_description/meshes/finger_flex_collision.stl</uri>
          </mesh>
        </geometry>
        <surface>
          <contact>
            <ode/>
          </contact>
          <friction>
            <ode/>
          </friction>
        </surface>
      </collision>
      <visual name='hand_middle_flex_2_link_visual'>
        <pose>0 0 0 0 -0 0</pose>
        <geometry>
          <mesh>
            <scale>1 1 1</scale>
            <uri>model://pal_hey5_description/meshes/finger_flex_collision.stl</uri>
          </mesh>
        </geometry>
        <material>
          <script>
            <name>Gazebo/Black</name>
            <uri>file://media/materials/scripts/gazebo.material</uri>
          </script>
        </material>
      </visual>
    </link>
    <joint name='hand_middle_virtual_3_joint' type='revolute'>
      <pose relative_to='hand_middle_flex_2_link'>0.009 0 0 0 -0 0</pose>
      <parent>hand_middle_flex_2_link</parent>
      <child>hand_middle_virtual_3_link</child>
      <axis>
        <xyz>0 0 1</xyz>
        <limit>
          <lower>0</lower>
          <upper>0.785398</upper>
          <effort>2</effort>
          <velocity>2</velocity>
        </limit>
        <dynamics>
          <damping>0.5</damping>
          <friction>0</friction>
          <spring_reference>0</spring_reference>
          <spring_stiffness>0</spring_stiffness>
        </dynamics>
      </axis>
    </joint>
    <link name='hand_middle_virtual_3_link'>
      <pose relative_to='hand_middle_virtual_3_joint'>0 0 0 0 -0 0</pose>
      <inertial>
        <pose>0.0065 0 0 0 -0 0</pose>
        <mass>0.01</mass>
        <inertia>
          <ixx>0.001</ixx>
          <ixy>0</ixy>
          <ixz>0</ixz>
          <iyy>0.001</iyy>
          <iyz>0</iyz>
          <izz>0.001</izz>
        </inertia>
      </inertial>
      <collision name='hand_middle_virtual_3_link_collision'>
        <pose>0 0 0 0 -0 0</pose>
        <geometry>
          <box>
            <size>0.013 0.002 0.012</size>
          </box>
        </geometry>
        <surface>
          <contact>
            <ode/>
          </contact>
          <friction>
            <ode/>
          </friction>
        </surface>
      </collision>
      <visual name='hand_middle_virtual_3_link_visual'>
        <pose>0.0065 0 0 0 -0 0</pose>
        <geometry>
          <box>
            <size>0.013 0.002 0.012</size>
          </box>
        </geometry>
        <material>
          <script>
            <name>Gazebo/Black</name>
            <uri>file://media/materials/scripts/gazebo.material</uri>
          </script>
        </material>
      </visual>
    </link>
    <joint name='hand_middle_flex_3_joint' type='revolute'>
      <pose relative_to='hand_middle_virtual_3_link'>0.013 0 0 0 -0 0</pose>
      <parent>hand_middle_virtual_3_link</parent>
      <child>hand_middle_flex_3_link</child>
      <axis>
        <xyz>0 0 1</xyz>
        <limit>
          <lower>0</lower>
          <upper>0.785398</upper>
          <effort>2</effort>
          <velocity>2</velocity>
        </limit>
        <dynamics>
          <damping>0.5</damping>
          <friction>0</friction>
          <spring_reference>0</spring_reference>
          <spring_stiffness>0</spring_stiffness>
        </dynamics>
      </axis>
    </joint>
    <link name='hand_middle_flex_3_link'>
      <pose relative_to='hand_middle_flex_3_joint'>0 0 0 0 -0 0</pose>
      <inertial>
        <pose>0.0096 0.003 0 0 -0 0</pose>
        <mass>0.015</mass>
        <inertia>
          <ixx>0.001</ixx>
          <ixy>0</ixy>
          <ixz>0</ixz>
          <iyy>0.001</iyy>
          <iyz>0</iyz>
          <izz>0.001</izz>
        </inertia>
      </inertial>
      <collision name='hand_middle_flex_3_link_collision'>
        <pose>0 0 0 0 -0 0</pose>
        <geometry>
          <mesh>
            <scale>1 1 1</scale>
            <uri>model://pal_hey5_description/meshes/finger_flex_tip_collision.stl</uri>
          </mesh>
        </geometry>
        <surface>
          <contact>
            <ode/>
          </contact>
          <friction>
            <ode/>
          </friction>
        </surface>
      </collision>
      <visual name='hand_middle_flex_3_link_visual'>
        <pose>0 0 0 0 -0 0</pose>
        <geometry>
          <mesh>
            <scale>1 1 1</scale>
            <uri>model://pal_hey5_description/meshes/finger_flex_tip_collision.stl</uri>
          </mesh>
        </geometry>
        <material>
          <script>
            <name>Gazebo/Black</name>
            <uri>file://media/materials/scripts/gazebo.material</uri>
          </script>
        </material>
      </visual>
    </link>
    <joint name='hand_mrl_joint' type='revolute'>
      <pose relative_to='wrist_ft_link'>0 0 0.012725 -1.5708 -1.5708 0</pose>
      <parent>wrist_ft_link</parent>
      <child>hand_mrl_link</child>
      <axis>
        <xyz>0 0 1</xyz>
        <limit>
          <lower>-2.53073</lower>
          <upper>9.25025</upper>
          <effort>2</effort>
          <velocity>3.56</velocity>
        </limit>
        <dynamics>
          <damping>0.5</damping>
          <friction>0</friction>
          <spring_reference>0</spring_reference>
          <spring_stiffness>0</spring_stiffness>
        </dynamics>
      </axis>
    </joint>
    <link name='hand_mrl_link'>
      <pose relative_to='hand_mrl_joint'>0 0 0 0 -0 0</pose>
      <inertial>
        <pose>0 0 0 0 -0 0</pose>
        <mass>0.05</mass>
        <inertia>
          <ixx>0.001</ixx>
          <ixy>0</ixy>
          <ixz>0</ixz>
          <iyy>0.001</iyy>
          <iyz>0</iyz>
          <izz>0.001</izz>
        </inertia>
      </inertial>
      <collision name='hand_mrl_link_collision'>
        <pose>0 0 0 0 -0 0</pose>
        <geometry>
          <sphere>
            <radius>0.001</radius>
          </sphere>
        </geometry>
      </collision>
      <visual name='hand_mrl_link_visual'>
        <pose>0 0 0 0 -0 0</pose>
        <geometry>
          <sphere>
            <radius>0.001</radius>
          </sphere>
        </geometry>
      </visual>
    </link>
    <joint name='hand_ring_abd_joint' type='revolute'>
      <pose relative_to='wrist_ft_link'>0.0042 -0.0125 0.139225 -1.5708 -1.309 -1.5708</pose>
      <parent>wrist_ft_link</parent>
      <child>hand_ring_abd_link</child>
      <axis>
        <xyz>0 0 1</xyz>
        <limit>
          <lower>-0.523599</lower>
          <upper>0.523599</upper>
          <effort>2</effort>
          <velocity>2</velocity>
        </limit>
        <dynamics>
          <damping>0.5</damping>
          <friction>0</friction>
          <spring_reference>0</spring_reference>
          <spring_stiffness>0</spring_stiffness>
        </dynamics>
      </axis>
    </joint>
    <link name='hand_ring_abd_link'>
      <pose relative_to='hand_ring_abd_joint'>0 0 0 0 -0 0</pose>
      <inertial>
        <pose>-0.0018 0 0.0028 0 -0 0</pose>
        <mass>0.018</mass>
        <inertia>
          <ixx>0.001</ixx>
          <ixy>0</ixy>
          <ixz>0</ixz>
          <iyy>0.001</iyy>
          <iyz>0</iyz>
          <izz>0.001</izz>
        </inertia>
      </inertial>
      <collision name='hand_ring_abd_link_collision'>
        <pose>0 0 0 0 -0 0</pose>
        <geometry>
          <mesh>
            <scale>1 1 1</scale>
            <uri>model://pal_hey5_description/meshes/finger_abd_collision.stl</uri>
          </mesh>
        </geometry>
        <surface>
          <contact>
            <ode/>
          </contact>
          <friction>
            <ode/>
          </friction>
        </surface>
      </collision>
      <visual name='hand_ring_abd_link_visual'>
        <pose>0 0 0 0 -0 0</pose>
        <geometry>
          <mesh>
            <scale>1 1 1</scale>
            <uri>model://pal_hey5_description/meshes/finger_abd_collision.stl</uri>
          </mesh>
        </geometry>
        <material>
          <script>
            <name>Gazebo/Black</name>
            <uri>file://media/materials/scripts/gazebo.material</uri>
          </script>
        </material>
      </visual>
    </link>
    <joint name='hand_ring_virtual_1_joint' type='revolute'>
      <pose relative_to='hand_ring_abd_link'>0.009 0 0 1.5708 -0 0</pose>
      <parent>hand_ring_abd_link</parent>
      <child>hand_ring_virtual_1_link</child>
      <axis>
        <xyz>0 0 1</xyz>
        <limit>
          <lower>0</lower>
          <upper>0.785398</upper>
          <effort>2</effort>
          <velocity>2</velocity>
        </limit>
        <dynamics>
          <damping>0.5</damping>
          <friction>0</friction>
          <spring_reference>0</spring_reference>
          <spring_stiffness>0</spring_stiffness>
        </dynamics>
      </axis>
    </joint>
    <link name='hand_ring_virtual_1_link'>
      <pose relative_to='hand_ring_virtual_1_joint'>0 0 0 0 -0 0</pose>
      <inertial>
        <pose>0.0065 0 0 0 -0 0</pose>
        <mass>0.01</mass>
        <inertia>
          <ixx>0.001</ixx>
          <ixy>0</ixy>
          <ixz>0</ixz>
          <iyy>0.001</iyy>
          <iyz>0</iyz>
          <izz>0.001</izz>
        </inertia>
      </inertial>
      <collision name='hand_ring_virtual_1_link_collision'>
        <pose>0 0 0 0 -0 0</pose>
        <geometry>
          <box>
            <size>0.013 0.002 0.012</size>
          </box>
        </geometry>
        <surface>
          <contact>
            <ode/>
          </contact>
          <friction>
            <ode/>
          </friction>
        </surface>
      </collision>
      <visual name='hand_ring_virtual_1_link_visual'>
        <pose>0.0065 0 0 0 -0 0</pose>
        <geometry>
          <box>
            <size>0.013 0.002 0.012</size>
          </box>
        </geometry>
        <material>
          <script>
            <name>Gazebo/Black</name>
            <uri>file://media/materials/scripts/gazebo.material</uri>
          </script>
        </material>
      </visual>
    </link>
    <joint name='hand_ring_flex_1_joint' type='revolute'>
      <pose relative_to='hand_ring_virtual_1_link'>0.013 0 0 0 -0 0</pose>
      <parent>hand_ring_virtual_1_link</parent>
      <child>hand_ring_flex_1_link</child>
      <axis>
        <xyz>0 0 1</xyz>
        <limit>
          <lower>0</lower>
          <upper>0.785398</upper>
          <effort>2</effort>
          <velocity>2</velocity>
        </limit>
        <dynamics>
          <damping>0.5</damping>
          <friction>0</friction>
          <spring_reference>0</spring_reference>
          <spring_stiffness>0</spring_stiffness>
        </dynamics>
      </axis>
    </joint>
    <link name='hand_ring_flex_1_link'>
      <pose relative_to='hand_ring_flex_1_joint'>0 0 0 0 -0 0</pose>
      <inertial>
        <pose>0.0047 0.0031 0 0 -0 0</pose>
        <mass>0.009</mass>
        <inertia>
          <ixx>0.001</ixx>
          <ixy>0</ixy>
          <ixz>0</ixz>
          <iyy>0.001</iyy>
          <iyz>0</iyz>
          <izz>0.001</izz>
        </inertia>
      </inertial>
      <collision name='hand_ring_flex_1_link_collision'>
        <pose>0 0 0 0 -0 0</pose>
        <geometry>
          <mesh>
            <scale>1 1 1</scale>
            <uri>model://pal_hey5_description/meshes/finger_flex_collision.stl</uri>
          </mesh>
        </geometry>
        <surface>
          <contact>
            <ode/>
          </contact>
          <friction>
            <ode/>
          </friction>
        </surface>
      </collision>
      <visual name='hand_ring_flex_1_link_visual'>
        <pose>0 0 0 0 -0 0</pose>
        <geometry>
          <mesh>
            <scale>1 1 1</scale>
            <uri>model://pal_hey5_description/meshes/finger_flex_collision.stl</uri>
          </mesh>
        </geometry>
        <material>
          <script>
            <name>Gazebo/Black</name>
            <uri>file://media/materials/scripts/gazebo.material</uri>
          </script>
        </material>
      </visual>
    </link>
    <joint name='hand_ring_virtual_2_joint' type='revolute'>
      <pose relative_to='hand_ring_flex_1_link'>0.009 0 0 0 -0 0</pose>
      <parent>hand_ring_flex_1_link</parent>
      <child>hand_ring_virtual_2_link</child>
      <axis>
        <xyz>0 0 1</xyz>
        <limit>
          <lower>0</lower>
          <upper>0.785398</upper>
          <effort>2</effort>
          <velocity>2</velocity>
        </limit>
        <dynamics>
          <damping>0.5</damping>
          <friction>0</friction>
          <spring_reference>0</spring_reference>
          <spring_stiffness>0</spring_stiffness>
        </dynamics>
      </axis>
    </joint>
    <link name='hand_ring_virtual_2_link'>
      <pose relative_to='hand_ring_virtual_2_joint'>0 0 0 0 -0 0</pose>
      <inertial>
        <pose>0.0065 0 0 0 -0 0</pose>
        <mass>0.01</mass>
        <inertia>
          <ixx>0.001</ixx>
          <ixy>0</ixy>
          <ixz>0</ixz>
          <iyy>0.001</iyy>
          <iyz>0</iyz>
          <izz>0.001</izz>
        </inertia>
      </inertial>
      <collision name='hand_ring_virtual_2_link_collision'>
        <pose>0 0 0 0 -0 0</pose>
        <geometry>
          <box>
            <size>0.013 0.002 0.012</size>
          </box>
        </geometry>
        <surface>
          <contact>
            <ode/>
          </contact>
          <friction>
            <ode/>
          </friction>
        </surface>
      </collision>
      <visual name='hand_ring_virtual_2_link_visual'>
        <pose>0.0065 0 0 0 -0 0</pose>
        <geometry>
          <box>
            <size>0.013 0.002 0.012</size>
          </box>
        </geometry>
        <material>
          <script>
            <name>Gazebo/Black</name>
            <uri>file://media/materials/scripts/gazebo.material</uri>
          </script>
        </material>
      </visual>
    </link>
    <joint name='hand_ring_flex_2_joint' type='revolute'>
      <pose relative_to='hand_ring_virtual_2_link'>0.013 0 0 0 -0 0</pose>
      <parent>hand_ring_virtual_2_link</parent>
      <child>hand_ring_flex_2_link</child>
      <axis>
        <xyz>0 0 1</xyz>
        <limit>
          <lower>0</lower>
          <upper>0.785398</upper>
          <effort>2</effort>
          <velocity>2</velocity>
        </limit>
        <dynamics>
          <damping>0.5</damping>
          <friction>0</friction>
          <spring_reference>0</spring_reference>
          <spring_stiffness>0</spring_stiffness>
        </dynamics>
      </axis>
    </joint>
    <link name='hand_ring_flex_2_link'>
      <pose relative_to='hand_ring_flex_2_joint'>0 0 0 0 -0 0</pose>
      <inertial>
        <pose>0.0047 0.0031 0 0 -0 0</pose>
        <mass>0.009</mass>
        <inertia>
          <ixx>0.001</ixx>
          <ixy>0</ixy>
          <ixz>0</ixz>
          <iyy>0.001</iyy>
          <iyz>0</iyz>
          <izz>0.001</izz>
        </inertia>
      </inertial>
      <collision name='hand_ring_flex_2_link_collision'>
        <pose>0 0 0 0 -0 0</pose>
        <geometry>
          <mesh>
            <scale>1 1 1</scale>
            <uri>model://pal_hey5_description/meshes/finger_flex_collision.stl</uri>
          </mesh>
        </geometry>
        <surface>
          <contact>
            <ode/>
          </contact>
          <friction>
            <ode/>
          </friction>
        </surface>
      </collision>
      <visual name='hand_ring_flex_2_link_visual'>
        <pose>0 0 0 0 -0 0</pose>
        <geometry>
          <mesh>
            <scale>1 1 1</scale>
            <uri>model://pal_hey5_description/meshes/finger_flex_collision.stl</uri>
          </mesh>
        </geometry>
        <material>
          <script>
            <name>Gazebo/Black</name>
            <uri>file://media/materials/scripts/gazebo.material</uri>
          </script>
        </material>
      </visual>
    </link>
    <joint name='hand_ring_virtual_3_joint' type='revolute'>
      <pose relative_to='hand_ring_flex_2_link'>0.009 0 0 0 -0 0</pose>
      <parent>hand_ring_flex_2_link</parent>
      <child>hand_ring_virtual_3_link</child>
      <axis>
        <xyz>0 0 1</xyz>
        <limit>
          <lower>0</lower>
          <upper>0.785398</upper>
          <effort>2</effort>
          <velocity>2</velocity>
        </limit>
        <dynamics>
          <damping>0.5</damping>
          <friction>0</friction>
          <spring_reference>0</spring_reference>
          <spring_stiffness>0</spring_stiffness>
        </dynamics>
      </axis>
    </joint>
    <link name='hand_ring_virtual_3_link'>
      <pose relative_to='hand_ring_virtual_3_joint'>0 0 0 0 -0 0</pose>
      <inertial>
        <pose>0.0065 0 0 0 -0 0</pose>
        <mass>0.01</mass>
        <inertia>
          <ixx>0.001</ixx>
          <ixy>0</ixy>
          <ixz>0</ixz>
          <iyy>0.001</iyy>
          <iyz>0</iyz>
          <izz>0.001</izz>
        </inertia>
      </inertial>
      <collision name='hand_ring_virtual_3_link_collision'>
        <pose>0 0 0 0 -0 0</pose>
        <geometry>
          <box>
            <size>0.013 0.002 0.012</size>
          </box>
        </geometry>
        <surface>
          <contact>
            <ode/>
          </contact>
          <friction>
            <ode/>
          </friction>
        </surface>
      </collision>
      <visual name='hand_ring_virtual_3_link_visual'>
        <pose>0.0065 0 0 0 -0 0</pose>
        <geometry>
          <box>
            <size>0.013 0.002 0.012</size>
          </box>
        </geometry>
        <material>
          <script>
            <name>Gazebo/Black</name>
            <uri>file://media/materials/scripts/gazebo.material</uri>
          </script>
        </material>
      </visual>
    </link>
    <joint name='hand_ring_flex_3_joint' type='revolute'>
      <pose relative_to='hand_ring_virtual_3_link'>0.013 0 0 0 -0 0</pose>
      <parent>hand_ring_virtual_3_link</parent>
      <child>hand_ring_flex_3_link</child>
      <axis>
        <xyz>0 0 1</xyz>
        <limit>
          <lower>0</lower>
          <upper>0.785398</upper>
          <effort>2</effort>
          <velocity>2</velocity>
        </limit>
        <dynamics>
          <damping>0.5</damping>
          <friction>0</friction>
          <spring_reference>0</spring_reference>
          <spring_stiffness>0</spring_stiffness>
        </dynamics>
      </axis>
    </joint>
    <link name='hand_ring_flex_3_link'>
      <pose relative_to='hand_ring_flex_3_joint'>0 0 0 0 -0 0</pose>
      <inertial>
        <pose>0.0096 0.003 0 0 -0 0</pose>
        <mass>0.015</mass>
        <inertia>
          <ixx>0.001</ixx>
          <ixy>0</ixy>
          <ixz>0</ixz>
          <iyy>0.001</iyy>
          <iyz>0</iyz>
          <izz>0.001</izz>
        </inertia>
      </inertial>
      <collision name='hand_ring_flex_3_link_collision'>
        <pose>0 0 0 0 -0 0</pose>
        <geometry>
          <mesh>
            <scale>1 1 1</scale>
            <uri>model://pal_hey5_description/meshes/finger_flex_tip_collision.stl</uri>
          </mesh>
        </geometry>
        <surface>
          <contact>
            <ode/>
          </contact>
          <friction>
            <ode/>
          </friction>
        </surface>
      </collision>
      <visual name='hand_ring_flex_3_link_visual'>
        <pose>0 0 0 0 -0 0</pose>
        <geometry>
          <mesh>
            <scale>1 1 1</scale>
            <uri>model://pal_hey5_description/meshes/finger_flex_tip_collision.stl</uri>
          </mesh>
        </geometry>
        <material>
          <script>
            <name>Gazebo/Black</name>
            <uri>file://media/materials/scripts/gazebo.material</uri>
          </script>
        </material>
      </visual>
    </link>
    <joint name='hand_thumb_abd_joint' type='revolute'>
      <pose relative_to='wrist_ft_link'>0.0134 0.038 0.102825 -3.14159 -0.436332 1.5708</pose>
      <parent>wrist_ft_link</parent>
      <child>hand_thumb_abd_link</child>
      <axis>
        <xyz>0 0 1</xyz>
        <limit>
          <lower>0</lower>
          <upper>1.5708</upper>
          <effort>2</effort>
          <velocity>2</velocity>
        </limit>
        <dynamics>
          <damping>0.5</damping>
          <friction>0</friction>
          <spring_reference>0</spring_reference>
          <spring_stiffness>0</spring_stiffness>
        </dynamics>
      </axis>
    </joint>
    <link name='hand_thumb_abd_link'>
      <pose relative_to='hand_thumb_abd_joint'>0 0 0 0 -0 0</pose>
      <inertial>
        <pose>-0.0132 0.0037 -0.0017 0 -0 0</pose>
        <mass>0.014</mass>
        <inertia>
          <ixx>0.001</ixx>
          <ixy>0</ixy>
          <ixz>0</ixz>
          <iyy>0.001</iyy>
          <iyz>0</iyz>
          <izz>0.001</izz>
        </inertia>
      </inertial>
      <collision name='hand_thumb_abd_link_collision'>
        <pose>0 0 0 0 -0 0</pose>
        <geometry>
          <mesh>
            <scale>1 1 1</scale>
            <uri>model://pal_hey5_description/meshes/thumb_abd_collision.stl</uri>
          </mesh>
        </geometry>
        <surface>
          <contact>
            <ode/>
          </contact>
          <friction>
            <ode/>
          </friction>
        </surface>
      </collision>
      <visual name='hand_thumb_abd_link_visual'>
        <pose>0 0 0 0 -0 0</pose>
        <geometry>
          <mesh>
            <scale>1 1 1</scale>
            <uri>model://pal_hey5_description/meshes/thumb_abd_collision.stl</uri>
          </mesh>
        </geometry>
        <material>
          <script>
            <name>Gazebo/Black</name>
            <uri>file://media/materials/scripts/gazebo.material</uri>
          </script>
        </material>
      </visual>
    </link>
    <joint name='hand_thumb_virtual_1_joint' type='revolute'>
      <pose relative_to='hand_thumb_abd_link'>0.0225 0.003 0 -1.14424 0 0</pose>
      <parent>hand_thumb_abd_link</parent>
      <child>hand_thumb_virtual_1_link</child>
      <axis>
        <xyz>0 0 1</xyz>
        <limit>
          <lower>0</lower>
          <upper>0.785398</upper>
          <effort>2</effort>
          <velocity>2</velocity>
        </limit>
        <dynamics>
          <damping>0.5</damping>
          <friction>0</friction>
          <spring_reference>0</spring_reference>
          <spring_stiffness>0</spring_stiffness>
        </dynamics>
      </axis>
    </joint>
    <link name='hand_thumb_virtual_1_link'>
      <pose relative_to='hand_thumb_virtual_1_joint'>0 0 0 0 -0 0</pose>
      <inertial>
        <pose>0.0065 0 0 0 -0 0</pose>
        <mass>0.01</mass>
        <inertia>
          <ixx>0.001</ixx>
          <ixy>0</ixy>
          <ixz>0</ixz>
          <iyy>0.001</iyy>
          <iyz>0</iyz>
          <izz>0.001</izz>
        </inertia>
      </inertial>
      <collision name='hand_thumb_virtual_1_link_collision'>
        <pose>0 0 0 0 -0 0</pose>
        <geometry>
          <box>
            <size>0.013 0.002 0.012</size>
          </box>
        </geometry>
        <surface>
          <contact>
            <ode/>
          </contact>
          <friction>
            <ode/>
          </friction>
        </surface>
      </collision>
      <visual name='hand_thumb_virtual_1_link_visual'>
        <pose>0.0065 0 0 0 -0 0</pose>
        <geometry>
          <box>
            <size>0.013 0.002 0.012</size>
          </box>
        </geometry>
        <material>
          <script>
            <name>Gazebo/Black</name>
            <uri>file://media/materials/scripts/gazebo.material</uri>
          </script>
        </material>
      </visual>
    </link>
    <joint name='hand_thumb_flex_1_joint' type='revolute'>
      <pose relative_to='hand_thumb_virtual_1_link'>0.013 0 0 0 -0 0</pose>
      <parent>hand_thumb_virtual_1_link</parent>
      <child>hand_thumb_flex_1_link</child>
      <axis>
        <xyz>0 0 1</xyz>
        <limit>
          <lower>0</lower>
          <upper>0.785398</upper>
          <effort>2</effort>
          <velocity>2</velocity>
        </limit>
        <dynamics>
          <damping>0.5</damping>
          <friction>0</friction>
          <spring_reference>0</spring_reference>
          <spring_stiffness>0</spring_stiffness>
        </dynamics>
      </axis>
    </joint>
    <link name='hand_thumb_flex_1_link'>
      <pose relative_to='hand_thumb_flex_1_joint'>0 0 0 0 -0 0</pose>
      <inertial>
        <pose>0.0047 0.0031 0 0 -0 0</pose>
        <mass>0.009</mass>
        <inertia>
          <ixx>0.001</ixx>
          <ixy>0</ixy>
          <ixz>0</ixz>
          <iyy>0.001</iyy>
          <iyz>0</iyz>
          <izz>0.001</izz>
        </inertia>
      </inertial>
      <collision name='hand_thumb_flex_1_link_collision'>
        <pose>0 0 0 0 -0 0</pose>
        <geometry>
          <mesh>
            <scale>1 1 1</scale>
            <uri>model://pal_hey5_description/meshes/finger_flex_collision.stl</uri>
          </mesh>
        </geometry>
        <surface>
          <contact>
            <ode/>
          </contact>
          <friction>
            <ode/>
          </friction>
        </surface>
      </collision>
      <visual name='hand_thumb_flex_1_link_visual'>
        <pose>0 0 0 0 -0 0</pose>
        <geometry>
          <mesh>
            <scale>1 1 1</scale>
            <uri>model://pal_hey5_description/meshes/finger_flex_collision.stl</uri>
          </mesh>
        </geometry>
        <material>
          <script>
            <name>Gazebo/Black</name>
            <uri>file://media/materials/scripts/gazebo.material</uri>
          </script>
        </material>
      </visual>
    </link>
    <joint name='hand_thumb_virtual_2_joint' type='revolute'>
      <pose relative_to='hand_thumb_flex_1_link'>0.009 0 0 0 -0 0</pose>
      <parent>hand_thumb_flex_1_link</parent>
      <child>hand_thumb_virtual_2_link</child>
      <axis>
        <xyz>0 0 1</xyz>
        <limit>
          <lower>0</lower>
          <upper>0.785398</upper>
          <effort>2</effort>
          <velocity>2</velocity>
        </limit>
        <dynamics>
          <damping>0.5</damping>
          <friction>0</friction>
          <spring_reference>0</spring_reference>
          <spring_stiffness>0</spring_stiffness>
        </dynamics>
      </axis>
    </joint>
    <link name='hand_thumb_virtual_2_link'>
      <pose relative_to='hand_thumb_virtual_2_joint'>0 0 0 0 -0 0</pose>
      <inertial>
        <pose>0.0065 0 0 0 -0 0</pose>
        <mass>0.01</mass>
        <inertia>
          <ixx>0.001</ixx>
          <ixy>0</ixy>
          <ixz>0</ixz>
          <iyy>0.001</iyy>
          <iyz>0</iyz>
          <izz>0.001</izz>
        </inertia>
      </inertial>
      <collision name='hand_thumb_virtual_2_link_collision'>
        <pose>0 0 0 0 -0 0</pose>
        <geometry>
          <box>
            <size>0.013 0.002 0.012</size>
          </box>
        </geometry>
        <surface>
          <contact>
            <ode/>
          </contact>
          <friction>
            <ode/>
          </friction>
        </surface>
      </collision>
      <visual name='hand_thumb_virtual_2_link_visual'>
        <pose>0.0065 0 0 0 -0 0</pose>
        <geometry>
          <box>
            <size>0.013 0.002 0.012</size>
          </box>
        </geometry>
        <material>
          <script>
            <name>Gazebo/Black</name>
            <uri>file://media/materials/scripts/gazebo.material</uri>
          </script>
        </material>
      </visual>
    </link>
    <joint name='hand_thumb_flex_2_joint' type='revolute'>
      <pose relative_to='hand_thumb_virtual_2_link'>0.013 0 0 0 -0 0</pose>
      <parent>hand_thumb_virtual_2_link</parent>
      <child>hand_thumb_flex_2_link</child>
      <axis>
        <xyz>0 0 1</xyz>
        <limit>
          <lower>0</lower>
          <upper>0.785398</upper>
          <effort>2</effort>
          <velocity>2</velocity>
        </limit>
        <dynamics>
          <damping>0.5</damping>
          <friction>0</friction>
          <spring_reference>0</spring_reference>
          <spring_stiffness>0</spring_stiffness>
        </dynamics>
      </axis>
    </joint>
    <link name='hand_thumb_flex_2_link'>
      <pose relative_to='hand_thumb_flex_2_joint'>0 0 0 0 -0 0</pose>
      <inertial>
        <pose>0.0096 0.003 0 0 -0 0</pose>
        <mass>0.015</mass>
        <inertia>
          <ixx>0.001</ixx>
          <ixy>0</ixy>
          <ixz>0</ixz>
          <iyy>0.001</iyy>
          <iyz>0</iyz>
          <izz>0.001</izz>
        </inertia>
      </inertial>
      <collision name='hand_thumb_flex_2_link_collision'>
        <pose>0 0 0 0 -0 0</pose>
        <geometry>
          <mesh>
            <scale>1 1 1</scale>
            <uri>model://pal_hey5_description/meshes/finger_flex_tip_collision.stl</uri>
          </mesh>
        </geometry>
        <surface>
          <contact>
            <ode/>
          </contact>
          <friction>
            <ode/>
          </friction>
        </surface>
      </collision>
      <visual name='hand_thumb_flex_2_link_visual'>
        <pose>0 0 0 0 -0 0</pose>
        <geometry>
          <mesh>
            <scale>1 1 1</scale>
            <uri>model://pal_hey5_description/meshes/finger_flex_tip_collision.stl</uri>
          </mesh>
        </geometry>
        <material>
          <script>
            <name>Gazebo/Black</name>
            <uri>file://media/materials/scripts/gazebo.material</uri>
          </script>
        </material>
      </visual>
    </link>
    <joint name='hand_thumb_joint' type='revolute'>
      <pose relative_to='wrist_ft_link'>0 0 0.012725 -1.5708 -1.5708 0</pose>
      <parent>wrist_ft_link</parent>
      <child>hand_thumb_link</child>
      <axis>
        <xyz>0 0 1</xyz>
        <limit>
          <lower>-2.61799</lower>
          <upper>6.28319</upper>
          <effort>2</effort>
          <velocity>3.35</velocity>
        </limit>
        <dynamics>
          <damping>0.5</damping>
          <friction>0</friction>
          <spring_reference>0</spring_reference>
          <spring_stiffness>0</spring_stiffness>
        </dynamics>
      </axis>
    </joint>
    <link name='hand_thumb_link'>
      <pose relative_to='hand_thumb_joint'>0 0 0 0 -0 0</pose>
      <inertial>
        <pose>0 0 0 0 -0 0</pose>
        <mass>0.05</mass>
        <inertia>
          <ixx>0.001</ixx>
          <ixy>0</ixy>
          <ixz>0</ixz>
          <iyy>0.001</iyy>
          <iyz>0</iyz>
          <izz>0.001</izz>
        </inertia>
      </inertial>
      <collision name='hand_thumb_link_collision'>
        <pose>0 0 0 0 -0 0</pose>
        <geometry>
          <sphere>
            <radius>0.001</radius>
          </sphere>
        </geometry>
      </collision>
      <visual name='hand_thumb_link_visual'>
        <pose>0 0 0 0 -0 0</pose>
        <geometry>
          <sphere>
            <radius>0.001</radius>
          </sphere>
        </geometry>
      </visual>
    </link>
    <joint name='head_1_joint' type='revolute'>
      <pose relative_to='torso_lift_link'>0.182 0 0 0 -0 0</pose>
      <parent>torso_lift_link</parent>
      <child>head_1_link</child>
      <axis>
        <xyz>0 0 1</xyz>
        <limit>
          <lower>-1.309</lower>
          <upper>1.309</upper>
          <effort>5.197</effort>
          <velocity>3</velocity>
        </limit>
        <dynamics>
          <damping>0.5</damping>
          <friction>1</friction>
          <spring_reference>0</spring_reference>
          <spring_stiffness>0</spring_stiffness>
        </dynamics>
      </axis>
      <physics>
        <ode>
          <implicit_spring_damper>1</implicit_spring_damper>
          <cfm_damping>1</cfm_damping>
          <limit>
            <cfm>0</cfm>
            <erp>0.2</erp>
          </limit>
        </ode>
      </physics>
    </joint>
    <link name='head_1_link'>
      <pose relative_to='head_1_joint'>0 0 0 0 -0 0</pose>
      <inertial>
        <pose>-0.00508 0.00237 0.07229 0 -0 0</pose>
        <mass>0.6222</mass>
        <inertia>
          <ixx>0.001192</ixx>
          <ixy>-7e-06</ixy>
          <ixz>9.6e-05</ixz>
          <iyy>0.001402</iyy>
          <iyz>4e-06</iyz>
          <izz>0.000889</izz>
        </inertia>
      </inertial>
      <collision name='head_1_link_collision'>
        <pose>0 0 0 0 -0 0</pose>
        <geometry>
          <mesh>
            <scale>1 1 1</scale>
            <uri>model://tiago_description/meshes/head/head_1_collision.dae</uri>
          </mesh>
        </geometry>
        <surface>
          <contact>
            <ode/>
          </contact>
          <friction>
            <ode>
              <mu>0.9</mu>
              <mu2>0.9</mu2>
            </ode>
          </friction>
        </surface>
      </collision>
      <visual name='head_1_link_visual'>
        <pose>0 0 0 0 -0 0</pose>
        <geometry>
          <mesh>
            <scale>1 1 1</scale>
            <uri>model://tiago_description/meshes/head/head_1.stl</uri>
          </mesh>
        </geometry>
      </visual>
    </link>
    <joint name='head_2_joint' type='revolute'>
      <pose relative_to='head_1_link'>0.005 0 0.098 1.5708 -0 0</pose>
      <parent>head_1_link</parent>
      <child>head_2_link</child>
      <axis>
        <xyz>0 0 1</xyz>
        <limit>
          <lower>-1.0472</lower>
          <upper>0.785398</upper>
          <effort>2.77</effort>
          <velocity>3</velocity>
        </limit>
        <dynamics>
          <damping>0.5</damping>
          <friction>1</friction>
          <spring_reference>0</spring_reference>
          <spring_stiffness>0</spring_stiffness>
        </dynamics>
      </axis>
    </joint>
    <link name='head_2_link'>
      <pose relative_to='head_2_joint'>0 0 0 0 -0 0</pose>
      <inertial>
        <pose>0.055827 0.060999 1.6e-05 0 -0 0</pose>
        <mass>0.88693</mass>
        <inertia>
          <ixx>0.00477062</ixx>
          <ixy>0.000560916</ixy>
          <ixz>1.19415e-05</ixz>
          <iyy>0.00513368</iyy>
          <iyz>9.32647e-06</iyz>
          <izz>0.00347598</izz>
        </inertia>
      </inertial>
      <collision name='head_2_link_collision'>
        <pose>0 0 0 0 -0 0</pose>
        <geometry>
          <mesh>
            <scale>1 1 1</scale>
            <uri>model://tiago_description/meshes/head/head_2_collision.dae</uri>
          </mesh>
        </geometry>
      </collision>
      <visual name='head_2_link_visual'>
        <pose>0 0 0 0 -0 0</pose>
        <geometry>
          <mesh>
            <scale>1 1 1</scale>
            <uri>model://tiago_description/meshes/head/head_2.stl</uri>
          </mesh>
        </geometry>
      </visual>
      <sensor name='head_front_camera_frame_sensor' type='depth'>
        <always_on>1</always_on>
        <update_rate>30</update_rate>
        <camera>
          <horizontal_fov>1.09956</horizontal_fov>
          <image>
            <format>B8G8R8</format>
            <width>640</width>
            <height>480</height>
          </image>
          <clip>
            <near>0.3</near>
            <far>8</far>
          </clip>
          <distortion>
            <k1>1e-08</k1>
            <k2>1e-08</k2>
            <k3>1e-08</k3>
            <p1>1e-08</p1>
            <p2>1e-08</p2>
          </distortion>
        </camera>
        <plugin name='head_front_camera_frame_controller' filename='libgazebo_ros_camera.so'>
          <camera_name>head_front_camera</camera_name>
          <ros>
            <remapping>head_front_camera/image_raw:=head_front_camera/rgb/image_raw</remapping>
            <remapping>head_front_camera/camera_info:=head_front_camera/rgb/camera_info</remapping>
            <remapping>head_front_camera/depth/image_raw:=head_front_camera/depth_registered/image_raw</remapping>
            <remapping>head_front_camera/depth/camera_info:=head_front_camera/depth_registered/camera_info</remapping>
            <remapping>head_front_camera/points:=head_front_camera/depth_registered/points</remapping>
          </ros>
          <frame_name>head_front_camera_rgb_optical_frame</frame_name>
          <min_depth>0.3</min_depth>
          <max_depth>8.0</max_depth>
        </plugin>
        <pose>0.0908 0.08 -0.022 -1.5708 0 0</pose>
      </sensor>
    </link>
    <plugin name='gazebo_ros_odometry' filename='libgazebo_world_odometry.so'>
      <frame_name>world</frame_name>
      <body_name>base_footprint</body_name>
      <topic_name>ground_truth_odom</topic_name>
      <update_rate>100.0</update_rate>
    </plugin>
    <static>0</static>
    <plugin name='gazebo_hand_thumb' filename='libgazebo_underactuated_finger.so'>
      <actuatedJoint>hand_thumb_joint</actuatedJoint>
      <virtualJoint>
        <name>hand_thumb_abd_joint</name>
        <scale_factor>2.0</scale_factor>
        <pid_gains>
          <p>50</p>
          <i>0.1</i>
          <d>0.1</d>
          <i_max>1</i_max>
          <i_min>-1</i_min>
        </pid_gains>
      </virtualJoint>
      <virtualJoint>
        <name>hand_thumb_flex_1_joint</name>
        <scale_factor>2.5</scale_factor>
        <pid_gains>
          <p>50</p>
          <i>0.1</i>
          <d>0.1</d>
          <i_max>1</i_max>
          <i_min>-1</i_min>
        </pid_gains>
      </virtualJoint>
      <virtualJoint>
        <name>hand_thumb_virtual_1_joint</name>
        <scale_factor>3.0</scale_factor>
        <pid_gains>
          <p>50</p>
          <i>0.1</i>
          <d>0.1</d>
          <i_max>1</i_max>
          <i_min>-1</i_min>
        </pid_gains>
      </virtualJoint>
      <virtualJoint>
        <name>hand_thumb_flex_2_joint</name>
        <scale_factor>3.5</scale_factor>
        <pid_gains>
          <p>50</p>
          <i>0.1</i>
          <d>0.1</d>
          <i_max>1</i_max>
          <i_min>-1</i_min>
        </pid_gains>
      </virtualJoint>
      <virtualJoint>
        <name>hand_thumb_virtual_2_joint</name>
        <scale_factor>3.0</scale_factor>
        <pid_gains>
          <p>50</p>
          <i>0.1</i>
          <d>0.1</d>
          <i_max>1</i_max>
          <i_min>-1</i_min>
        </pid_gains>
      </virtualJoint>
    </plugin>
    <plugin name='gazebo_hand_index' filename='libgazebo_underactuated_finger.so'>
      <actuatedJoint>hand_index_joint</actuatedJoint>
      <virtualJoint>
        <name>hand_index_abd_joint</name>
        <scale_factor>5.0</scale_factor>
        <pid_gains>
          <p>50</p>
          <i>0.1</i>
          <d>0.1</d>
          <i_max>1</i_max>
          <i_min>-1</i_min>
        </pid_gains>
      </virtualJoint>
      <virtualJoint>
        <name>hand_index_flex_1_joint</name>
        <scale_factor>2.5</scale_factor>
        <pid_gains>
          <p>50</p>
          <i>0.1</i>
          <d>0.1</d>
          <i_max>1</i_max>
          <i_min>-1</i_min>
        </pid_gains>
      </virtualJoint>
      <virtualJoint>
        <name>hand_index_virtual_1_joint</name>
        <scale_factor>3.0</scale_factor>
        <pid_gains>
          <p>50</p>
          <i>0.1</i>
          <d>0.1</d>
          <i_max>1</i_max>
          <i_min>-1</i_min>
        </pid_gains>
      </virtualJoint>
      <virtualJoint>
        <name>hand_index_flex_2_joint</name>
        <scale_factor>3.5</scale_factor>
        <pid_gains>
          <p>50</p>
          <i>0.1</i>
          <d>0.1</d>
          <i_max>1</i_max>
          <i_min>-1</i_min>
        </pid_gains>
      </virtualJoint>
      <virtualJoint>
        <name>hand_index_virtual_2_joint</name>
        <scale_factor>3.5</scale_factor>
        <pid_gains>
          <p>50</p>
          <i>0.1</i>
          <d>0.1</d>
          <i_max>1</i_max>
          <i_min>-1</i_min>
        </pid_gains>
      </virtualJoint>
      <virtualJoint>
        <name>hand_index_flex_3_joint</name>
        <scale_factor>4.0</scale_factor>
        <pid_gains>
          <p>50</p>
          <i>0.1</i>
          <d>0.1</d>
          <i_max>1</i_max>
          <i_min>-1</i_min>
        </pid_gains>
      </virtualJoint>
    </plugin>
    <plugin name='gazebo_hand_middle' filename='libgazebo_underactuated_finger.so'>
      <actuatedJoint>hand_mrl_joint</actuatedJoint>
      <virtualJoint>
        <name>hand_middle_flex_1_joint</name>
        <scale_factor>2.5</scale_factor>
        <pid_gains>
          <p>50</p>
          <i>0.1</i>
          <d>0.1</d>
          <i_max>1</i_max>
          <i_min>-1</i_min>
        </pid_gains>
      </virtualJoint>
      <virtualJoint>
        <name>hand_middle_virtual_1_joint</name>
        <scale_factor>3.0</scale_factor>
        <pid_gains>
          <p>50</p>
          <i>0.1</i>
          <d>0.1</d>
          <i_max>1</i_max>
          <i_min>-1</i_min>
        </pid_gains>
      </virtualJoint>
      <virtualJoint>
        <name>hand_middle_flex_2_joint</name>
        <scale_factor>3.5</scale_factor>
        <pid_gains>
          <p>50</p>
          <i>0.1</i>
          <d>0.1</d>
          <i_max>1</i_max>
          <i_min>-1</i_min>
        </pid_gains>
      </virtualJoint>
      <virtualJoint>
        <name>hand_middle_virtual_2_joint</name>
        <scale_factor>3.5</scale_factor>
        <pid_gains>
          <p>50</p>
          <i>0.1</i>
          <d>0.1</d>
          <i_max>1</i_max>
          <i_min>-1</i_min>
        </pid_gains>
      </virtualJoint>
      <virtualJoint>
        <name>hand_middle_flex_3_joint</name>
        <scale_factor>4.0</scale_factor>
        <pid_gains>
          <p>50</p>
          <i>0.1</i>
          <d>0.1</d>
          <i_max>1</i_max>
          <i_min>-1</i_min>
        </pid_gains>
      </virtualJoint>
    </plugin>
    <plugin name='gazebo_hand_ring' filename='libgazebo_underactuated_finger.so'>
      <actuatedJoint>hand_mrl_joint</actuatedJoint>
      <virtualJoint>
        <name>hand_ring_flex_1_joint</name>
        <scale_factor>2.5</scale_factor>
        <pid_gains>
          <p>50</p>
          <i>0.1</i>
          <d>0.1</d>
          <i_max>1</i_max>
          <i_min>-1</i_min>
        </pid_gains>
      </virtualJoint>
      <virtualJoint>
        <name>hand_ring_virtual_1_joint</name>
        <scale_factor>3.0</scale_factor>
        <pid_gains>
          <p>50</p>
          <i>0.1</i>
          <d>0.1</d>
          <i_max>1</i_max>
          <i_min>-1</i_min>
        </pid_gains>
      </virtualJoint>
      <virtualJoint>
        <name>hand_ring_flex_2_joint</name>
        <scale_factor>3.5</scale_factor>
        <pid_gains>
          <p>50</p>
          <i>0.1</i>
          <d>0.1</d>
          <i_max>1</i_max>
          <i_min>-1</i_min>
        </pid_gains>
      </virtualJoint>
      <virtualJoint>
        <name>hand_ring_virtual_2_joint</name>
        <scale_factor>3.5</scale_factor>
        <pid_gains>
          <p>50</p>
          <i>0.1</i>
          <d>0.1</d>
          <i_max>1</i_max>
          <i_min>-1</i_min>
        </pid_gains>
      </virtualJoint>
      <virtualJoint>
        <name>hand_ring_flex_3_joint</name>
        <scale_factor>4.0</scale_factor>
        <pid_gains>
          <p>50</p>
          <i>0.1</i>
          <d>0.1</d>
          <i_max>1</i_max>
          <i_min>-1</i_min>
        </pid_gains>
      </virtualJoint>
    </plugin>
    <plugin name='gazebo_hand_little' filename='libgazebo_underactuated_finger.so'>
      <actuatedJoint>hand_mrl_joint</actuatedJoint>
      <virtualJoint>
        <name>hand_little_flex_1_joint</name>
        <scale_factor>2.5</scale_factor>
        <pid_gains>
          <p>50</p>
          <i>0.1</i>
          <d>0.1</d>
          <i_max>1</i_max>
          <i_min>-1</i_min>
        </pid_gains>
      </virtualJoint>
      <virtualJoint>
        <name>hand_little_virtual_1_joint</name>
        <scale_factor>3.0</scale_factor>
        <pid_gains>
          <p>50</p>
          <i>0.1</i>
          <d>0.1</d>
          <i_max>1</i_max>
          <i_min>-1</i_min>
        </pid_gains>
      </virtualJoint>
      <virtualJoint>
        <name>hand_little_flex_2_joint</name>
        <scale_factor>3.5</scale_factor>
        <pid_gains>
          <p>50</p>
          <i>0.1</i>
          <d>0.1</d>
          <i_max>1</i_max>
          <i_min>-1</i_min>
        </pid_gains>
      </virtualJoint>
      <virtualJoint>
        <name>hand_little_virtual_2_joint</name>
        <scale_factor>3.5</scale_factor>
        <pid_gains>
          <p>50</p>
          <i>0.1</i>
          <d>0.1</d>
          <i_max>1</i_max>
          <i_min>-1</i_min>
        </pid_gains>
      </virtualJoint>
      <virtualJoint>
        <name>hand_little_flex_3_joint</name>
        <scale_factor>4.0</scale_factor>
        <pid_gains>
          <p>50</p>
          <i>0.1</i>
          <d>0.1</d>
          <i_max>1</i_max>
          <i_min>-1</i_min>
        </pid_gains>
      </virtualJoint>
    </plugin>
  </model>
</sdf>
